Workbook

Sheet FC SALE
A3: THÁNG | B3: NGÀY | C3: THỨ | D3: FC SALE 30% | E3: FC SALE 70%
B4: 1 | C4: MON | D4: 3000000 | E4: 6000000
B5: =B4+1 -> 2 | C5: TUE | D5: 3000000 | E5: 6000000
B6: =B5+1 -> 3 | C6: WED | D6: 3000000 | E6: 6000000
B7: =B6+1 -> 4 | C7: THU | D7: 3000000 | E7: 6000000
B8: =B7+1 -> 5 | C8: FRI | D8: 3000000 | E8: 6000000
B9: =B8+1 -> 6 | C9: SAT | D9: 3000000 | E9: 6000000
B10: =B9+1 -> 7 | C10: SUN | D10: 3000000 | E10: 6000000 | O10: S
B11: =B10+1 -> 8 | C11: MON | D11: 3000000 | E11: 6000000
B12: =B11+1 -> 9 | C12: TUE | D12: 3000000 | E12: 6000000
B13: =B12+1 -> 10 | C13: WED | D13: 3000000 | E13: 6000000
B14: =B13+1 -> 11 | C14: THU | D14: 3000000 | E14: 6000000
A15: TOTAL | D15: =SUM(D4:D14) -> 33000000 | E15: =SUM(E4:E14) -> 66000000

Sheet ĐƠN RAU
A2: DOANH THU THÁNG | E2: 10000000 | H2: CÔNG TY TNHH KIDO EDU
H4: Trường : | I4: KIDO | Q4: Weekly Sales Trend | AM4: NCC/CK | AO4: CK | AQ4: CK | AS4: CK | AU4: NCC | AW4: CK
F6: Kế hoạch đặt hàng hóa trong Tuần | Q6: 35000000 | R6: 35000000 | X6: 30000000 | Y6: 30000000 | Z6: 30000000 | AA6: 45000000 | AB6: 45000000 | AC6: 70000000 | AD6: 70000000 | AE6: 70000000 | AF6: 60000000 | AG6: 40000000 | AH6: 40000000 | AI6: 60000000 | AJ6: 60000000 | AK6: 50000000 | AM6: 28 TET | AO6: MUNG 2 | AQ6: MUNG 3 | AS6: MUNG 5 | AU6: MUNG 6 | AW6: MUNG 9
Q7: PHÂN BỔ SỐ LƯỢNG HÀNG NHẬP TRONG TUẦN | AM7: D1 | AO7: D2 | AQ7: D' | AS7: D3 | AU7: D2 | AW7: D4
X8: 27 Tết | Y8: 28 Tết | Z8: 29 Tết | AA8: 30 Tết | AB8: Mùng 1 | AC8: Mùng 2 | AD8: Mùng 3 | AE8: Mùng 4 | AF8: Mùng 5 | AG8: Mùng 6 | AH8: Mùng 7 | AI8: Mùng 8 | AJ8: Mùng 9 | AK8: Mùng 10 | AQ8: HANG NHAP GUI TAI CK
A9: STT | B9: NHÓM | C9: TÊN NHÀ CUNG CẤP | D9: CODE | E9: TÊN HÀNG | F9: ĐVT | G9: MOQ | H9: Số xuất dùng của tháng theo doanh thu | I9: Tồn Kiểm Kê | J9: Plan Sales cho thời gian nhập hàng tới: | N9: ='FC SALE'!D15 -> 33000000 | O9: Số cần đặt sau điều chỉnh ( nhập PM ) | Q9: 44228 | R9: =Q9+1 -> 44229 | S9: =R9+1 -> 44230 | T9: =S9+1 -> 44231 | U9: =T9+1 -> 44232 | V9: =U9+1 -> 44233 | W9: =V9+1 -> 44234 | X9: =W9+1 -> 44235 | Y9: =X9+1 -> 44236 | ... AK9: =AJ9+1 -> 44248
J10: Usage per Mil | K10: Min | L10: Max | M10: Báo động | N10: Số cần đặt thêm | Q10: =Q6/$N$9 -> 1.0606061 | R10: =R6/$N$9 -> 1.0606061 | S10: =S6/$N$9 -> 0 | T10: =T6/$N$9 -> 0 | U10: =U6/$N$9 -> 0 | V10: =V6/$N$9 -> 0 | W10: =W6/$N$9 -> 0 | X10: =X6/$N$9 -> 0.90909091 | ... AK10: =AK6/$N$9 -> 1.5151515
K11: 1.2 | L11: 1.5
A12: 1 | G12: Không yêu cầu | H12: 3 | I12: 10 | J12: =IF(ISERROR(1000000*H12/$E$2),"",1000000*H12/$E$2) -> 0.3 | K12: =J12*$K$11*$N$9/1000000 -> 11.88 | L12: =J12*$L$11*$N$9/1000000 -> 14.85 | M12: =IF(I12<K12,"Cần order thêm",IF(I12>L12,"Quá nhiều hàng tồn","")) -> Cần order thêm | N12: =IF(M12="Cần order thêm",L12-I12,"") -> 4.85 | Q12: =$N12*$Q$10 -> 5.1439394 | R12: =$N12*$R$10 -> 5.1439394 | S12: =$N12*$S$10 -> 0 | T12: =$N12*$T$10 -> 0 | U12: =$N12*$U$10 -> 0 | V12: =$N12*$V$10 -> 0 | W12: =$N12*$W$10 -> 0 | X12: =$N12*$X$10 -> 4.4090909 | Y12: =$N12*$Y$10 -> 4.4090909 | Z12: =$N12*$Z$10 -> 4.4090909 | AA12: =$N12*$AA$10 -> 6.6136364 | AB12: =$N12*$AB$10 -> 6.6136364 | AC12: =$N12*$AC$10 -> 10.287879 | AD12: =$N12*$AD$10 -> 10.287879 | AE12: =$N12*$AE$10 -> 10.287879 | AF12: =$N12*$AF$10 -> 8.8181818 | AG12: =$N12*$AG$10 -> 5.8787879 | AH12: =$N12*$AH$10 -> 5.8787879 | AI12: =$N12*$AI$10 -> 8.8181818 | AJ12: =$N12*$AJ$10 -> 8.8181818 | AK12: =$N12*$AK$10 -> 7.3484848 | AM12: 5000 | AU12: 5000 | AX12: =SUM(AM12:AW12) -> 10000
A13: =A12+1 -> 2 | G13: 500000 | J13: =IF(ISERROR(1000000*H13/$E$2),"",1000000*H13/$E$2) -> 0 | K13: =J13*$K$11*$N$9/1000000 -> 0 | L13: =J13*$L$11*$N$9/1000000 -> 0 | M13: =IF(I13<K13,"Cần order thêm",IF(I13>L13,"Quá nhiều hàng tồn","")) | N13: =IF(M13="Cần order thêm",L13-I13,"") | Q13: =$N13*$Q$10 -> #VALUE! | R13: =$N13*$R$10 -> #VALUE! | S13: =$N13*$S$10 -> #VALUE! | T13: =$N13*$T$10 -> #VALUE! | U13: =$N13*$U$10 -> #VALUE! | V13: =$N13*$V$10 -> #VALUE! | W13: =$N13*$W$10 -> #VALUE! | X13: =$N13*$X$10 -> #VALUE! | Y13: =$N13*$Y$10 -> #VALUE! | Z13: =$N13*$Z$10 -> #VALUE! | AA13: =$N13*$AA$10 -> #VALUE! | AB13: =$N13*$AB$10 -> #VALUE! | AC13: =$N13*$AC$10 -> #VALUE! | AD13: =$N13*$AD$10 -> #VALUE! | AE13: =$N13*$AE$10 -> #VALUE! | AF13: =$N13*$AF$10 -> #VALUE! | AG13: =$N13*$AG$10 -> #VALUE! | AH13: =$N13*$AH$10 -> #VALUE! | AI13: =$N13*$AI$10 -> #VALUE! | AJ13: =$N13*$AJ$10 -> #VALUE! | AK13: =$N13*$AK$10 -> #VALUE! | AM13: 35000 | AQ13: 30000 | AU13: 30000 | AX13: =SUM(AM13:AW13) -> 95000
A14: =A13+1 -> 3 | J14: =IF(ISERROR(1000000*H14/$E$2),"",1000000*H14/$E$2) -> 0 | K14: =J14*$K$11*$N$9/1000000 -> 0 | L14: =J14*$L$11*$N$9/1000000 -> 0 | M14: =IF(I14<K14,"Cần order thêm",IF(I14>L14,"Quá nhiều hàng tồn","")) | N14: =IF(M14="Cần order thêm",L14-I14,"")
A15: =A14+1 -> 4 | G15: Không yêu cầu | J15: =IF(ISERROR(1000000*H15/$E$2),"",1000000*H15/$E$2) -> 0 | K15: =J15*$K$11*$N$9/1000000 -> 0 | L15: =J15*$L$11*$N$9/1000000 -> 0 | M15: =IF(I15<K15,"Cần order thêm",IF(I15>L15,"Quá nhiều hàng tồn","")) | N15: =IF(M15="Cần order thêm",L15-I15,"") | Q15: =$N15*$Q$10 -> #VALUE! | R15: =$N15*$R$10 -> #VALUE! | S15: =$N15*$S$10 -> #VALUE! | T15: =$N15*$T$10 -> #VALUE! | U15: =$N15*$U$10 -> #VALUE! | V15: =$N15*$V$10 -> #VALUE! | W15: =$N15*$W$10 -> #VALUE! | X15: =$N15*$X$10 -> #VALUE! | Y15: =$N15*$Y$10 -> #VALUE! | Z15: =$N15*$Z$10 -> #VALUE! | AA15: =$N15*$AA$10 -> #VALUE! | AB15: =$N15*$AB$10 -> #VALUE! | AC15: =$N15*$AC$10 -> #VALUE! | AD15: =$N15*$AD$10 -> #VALUE! | AE15: =$N15*$AE$10 -> #VALUE! | AF15: =$N15*$AF$10 -> #VALUE! | AG15: =$N15*$AG$10 -> #VALUE! | AH15: =$N15*$AH$10 -> #VALUE! | AI15: =$N15*$AI$10 -> #VALUE! | AJ15: =$N15*$AJ$10 -> #VALUE! | AK15: =$N15*$AK$10 -> #VALUE! | AX15: =SUM(AM15:AW15) -> 0
A16: =A15+1 -> 5 | G16: Không yêu cầu | J16: =IF(ISERROR(1000000*H16/$E$2),"",1000000*H16/$E$2) -> 0 | K16: =J16*$K$11*$N$9/1000000 -> 0 | L16: =J16*$L$11*$N$9/1000000 -> 0 | M16: =IF(I16<K16,"Cần order thêm",IF(I16>L16,"Quá nhiều hàng tồn","")) | N16: =IF(M16="Cần order thêm",L16-I16,"") | Q16: =$N16*$Q$10 -> #VALUE! | R16: =$N16*$R$10 -> #VALUE! | S16: =$N16*$S$10 -> #VALUE! | T16: =$N16*$T$10 -> #VALUE! | U16: =$N16*$U$10 -> #VALUE! | V16: =$N16*$V$10 -> #VALUE! | W16: =$N16*$W$10 -> #VALUE! | X16: =$N16*$X$10 -> #VALUE! | Y16: =$N16*$Y$10 -> #VALUE! | Z16: =$N16*$Z$10 -> #VALUE! | AA16: =$N16*$AA$10 -> #VALUE! | AB16: =$N16*$AB$10 -> #VALUE! | AC16: =$N16*$AC$10 -> #VALUE! | AD16: =$N16*$AD$10 -> #VALUE! | AE16: =$N16*$AE$10 -> #VALUE! | AF16: =$N16*$AF$10 -> #VALUE! | AG16: =$N16*$AG$10 -> #VALUE! | AH16: =$N16*$AH$10 -> #VALUE! | AI16: =$N16*$AI$10 -> #VALUE! | AJ16: =$N16*$AJ$10 -> #VALUE! | AK16: =$N16*$AK$10 -> #VALUE! | AM16: 300000 | AO16: 450000 | AS16: 350000 | AW16: 300000 | AX16: =SUM(AM16:AW16) -> 1400000
A17: =A16+1 -> 6 | G17: 500000 | J17: =IF(ISERROR(1000000*H17/$E$2),"",1000000*H17/$E$2) -> 0 | K17: =J17*$K$11*$N$9/1000000 -> 0 | L17: =J17*$L$11*$N$9/1000000 -> 0 | M17: =IF(I17<K17,"Cần order thêm",IF(I17>L17,"Quá nhiều hàng tồn","")) | N17: =IF(M17="Cần order thêm",L17-I17,"") | Q17: =$N17*$Q$10 -> #VALUE! | R17: =$N17*$R$10 -> #VALUE! | S17: =$N17*$S$10 -> #VALUE! | T17: =$N17*$T$10 -> #VALUE! | U17: =$N17*$U$10 -> #VALUE! | V17: =$N17*$V$10 -> #VALUE! | W17: =$N17*$W$10 -> #VALUE! | X17: =$N17*$X$10 -> #VALUE! | Y17: =$N17*$Y$10 -> #VALUE! | Z17: =$N17*$Z$10 -> #VALUE! | AA17: =$N17*$AA$10 -> #VALUE! | AB17: =$N17*$AB$10 -> #VALUE! | AC17: =$N17*$AC$10 -> #VALUE! | AD17: =$N17*$AD$10 -> #VALUE! | AE17: =$N17*$AE$10 -> #VALUE! | AF17: =$N17*$AF$10 -> #VALUE! | AG17: =$N17*$AG$10 -> #VALUE! | AH17: =$N17*$AH$10 -> #VALUE! | AI17: =$N17*$AI$10 -> #VALUE! | AJ17: =$N17*$AJ$10 -> #VALUE! | AK17: =$N17*$AK$10 -> #VALUE! | AM17: 20000 | AQ17: 20000 | AU17: 20000 | AX17: =SUM(AM17:AW17) -> 60000
A18: =A17+1 -> 7 | G18: Không yêu cầu | J18: =IF(ISERROR(1000000*H18/$E$2),"",1000000*H18/$E$2) -> 0 | K18: =J18*$K$11*$N$9/1000000 -> 0 | L18: =J18*$L$11*$N$9/1000000 -> 0 | M18: =IF(I18<K18,"Cần order thêm",IF(I18>L18,"Quá nhiều hàng tồn","")) | N18: =IF(M18="Cần order thêm",L18-I18,"") | Q18: =$N18*$Q$10 -> #VALUE! | R18: =$N18*$R$10 -> #VALUE! | S18: =$N18*$S$10 -> #VALUE! | T18: =$N18*$T$10 -> #VALUE! | U18: =$N18*$U$10 -> #VALUE! | V18: =$N18*$V$10 -> #VALUE! | W18: =$N18*$W$10 -> #VALUE! | X18: =$N18*$X$10 -> #VALUE! | Y18: =$N18*$Y$10 -> #VALUE! | Z18: =$N18*$Z$10 -> #VALUE! | AA18: =$N18*$AA$10 -> #VALUE! | AB18: =$N18*$AB$10 -> #VALUE! | AC18: =$N18*$AC$10 -> #VALUE! | AD18: =$N18*$AD$10 -> #VALUE! | AE18: =$N18*$AE$10 -> #VALUE! | AF18: =$N18*$AF$10 -> #VALUE! | AG18: =$N18*$AG$10 -> #VALUE! | AH18: =$N18*$AH$10 -> #VALUE! | AI18: =$N18*$AI$10 -> #VALUE! | AJ18: =$N18*$AJ$10 -> #VALUE! | AK18: =$N18*$AK$10 -> #VALUE! | AM18: 50000 | AO18: 60000 | AS18: 50000 | AW18: 50000 | AX18: =SUM(AM18:AW18) -> 210000
A19: =A18+1 -> 8 | G19: 1000000 | J19: =IF(ISERROR(1000000*H19/$E$2),"",1000000*H19/$E$2) -> 0 | K19: =J19*$K$11*$N$9/1000000 -> 0 | L19: =J19*$L$11*$N$9/1000000 -> 0 | M19: =IF(I19<K19,"Cần order thêm",IF(I19>L19,"Quá nhiều hàng tồn","")) | N19: =IF(M19="Cần order thêm",L19-I19,"") | Q19: =$N19*$Q$10 -> #VALUE! | R19: =$N19*$R$10 -> #VALUE! | S19: =$N19*$S$10 -> #VALUE! | T19: =$N19*$T$10 -> #VALUE! | U19: =$N19*$U$10 -> #VALUE! | V19: =$N19*$V$10 -> #VALUE! | W19: =$N19*$W$10 -> #VALUE! | X19: =$N19*$X$10 -> #VALUE! | Y19: =$N19*$Y$10 -> #VALUE! | Z19: =$N19*$Z$10 -> #VALUE! | AA19: =$N19*$AA$10 -> #VALUE! | AB19: =$N19*$AB$10 -> #VALUE! | AC19: =$N19*$AC$10 -> #VALUE! | AD19: =$N19*$AD$10 -> #VALUE! | AE19: =$N19*$AE$10 -> #VALUE! | AF19: =$N19*$AF$10 -> #VALUE! | AG19: =$N19*$AG$10 -> #VALUE! | AH19: =$N19*$AH$10 -> #VALUE! | AI19: =$N19*$AI$10 -> #VALUE! | AJ19: =$N19*$AJ$10 -> #VALUE! | AK19: =$N19*$AK$10 -> #VALUE! | AM19: 12000 | AQ19: 12000 | AU19: 12000 | AX19: =SUM(AM19:AW19) -> 36000
A20: =A19+1 -> 9 | G20: 1000000 | J20: =IF(ISERROR(1000000*H20/$E$2),"",1000000*H20/$E$2) -> 0 | K20: =J20*$K$11*$N$9/1000000 -> 0 | L20: =J20*$L$11*$N$9/1000000 -> 0 | M20: =IF(I20<K20,"Cần order thêm",IF(I20>L20,"Quá nhiều hàng tồn","")) | N20: =IF(M20="Cần order thêm",L20-I20,"") | Q20: =$N20*$Q$10 -> #VALUE! | R20: =$N20*$R$10 -> #VALUE! | S20: =$N20*$S$10 -> #VALUE! | T20: =$N20*$T$10 -> #VALUE! | U20: =$N20*$U$10 -> #VALUE! | V20: =$N20*$V$10 -> #VALUE! | W20: =$N20*$W$10 -> #VALUE! | X20: =$N20*$X$10 -> #VALUE! | Y20: =$N20*$Y$10 -> #VALUE! | Z20: =$N20*$Z$10 -> #VALUE! | AA20: =$N20*$AA$10 -> #VALUE! | AB20: =$N20*$AB$10 -> #VALUE! | AC20: =$N20*$AC$10 -> #VALUE! | AD20: =$N20*$AD$10 -> #VALUE! | AE20: =$N20*$AE$10 -> #VALUE! | AF20: =$N20*$AF$10 -> #VALUE! | AG20: =$N20*$AG$10 -> #VALUE! | AH20: =$N20*$AH$10 -> #VALUE! | AI20: =$N20*$AI$10 -> #VALUE! | AJ20: =$N20*$AJ$10 -> #VALUE! | AK20: =$N20*$AK$10 -> #VALUE! | AM20: 70000 | AQ20: 70000 | AU20: 70000 | AX20: =SUM(AM20:AW20) -> 210000
A21: =A20+1 -> 10 | G21: Không yêu cầu | J21: =IF(ISERROR(1000000*H21/$E$2),"",1000000*H21/$E$2) -> 0 | K21: =J21*$K$11*$N$9/1000000 -> 0 | L21: =J21*$L$11*$N$9/1000000 -> 0 | M21: =IF(I21<K21,"Cần order thêm",IF(I21>L21,"Quá nhiều hàng tồn","")) | N21: =IF(M21="Cần order thêm",L21-I21,"") | Q21: =$N21*$Q$10 -> #VALUE! | R21: =$N21*$R$10 -> #VALUE! | S21: =$N21*$S$10 -> #VALUE! | T21: =$N21*$T$10 -> #VALUE! | U21: =$N21*$U$10 -> #VALUE! | V21: =$N21*$V$10 -> #VALUE! | W21: =$N21*$W$10 -> #VALUE! | X21: =$N21*$X$10 -> #VALUE! | Y21: =$N21*$Y$10 -> #VALUE! | Z21: =$N21*$Z$10 -> #VALUE! | AA21: =$N21*$AA$10 -> #VALUE! | AB21: =$N21*$AB$10 -> #VALUE! | AC21: =$N21*$AC$10 -> #VALUE! | AD21: =$N21*$AD$10 -> #VALUE! | AE21: =$N21*$AE$10 -> #VALUE! | AF21: =$N21*$AF$10 -> #VALUE! | AG21: =$N21*$AG$10 -> #VALUE! | AH21: =$N21*$AH$10 -> #VALUE! | AI21: =$N21*$AI$10 -> #VALUE! | AJ21: =$N21*$AJ$10 -> #VALUE! | AK21: =$N21*$AK$10 -> #VALUE! | AM21: 10000 | AO21: 10000 | AS21: 10000 | AW21: 10000 | AX21: =SUM(AM21:AW21) -> 40000
A22: =A21+1 -> 11 | G22: 1000000 | J22: =IF(ISERROR(1000000*H22/$E$2),"",1000000*H22/$E$2) -> 0 | K22: =J22*$K$11*$N$9/1000000 -> 0 | L22: =J22*$L$11*$N$9/1000000 -> 0 | M22: =IF(I22<K22,"Cần order thêm",IF(I22>L22,"Quá nhiều hàng tồn","")) | N22: =IF(M22="Cần order thêm",L22-I22,"") | Q22: =$N22*$Q$10 -> #VALUE! | R22: =$N22*$R$10 -> #VALUE! | S22: =$N22*$S$10 -> #VALUE! | T22: =$N22*$T$10 -> #VALUE! | U22: =$N22*$U$10 -> #VALUE! | V22: =$N22*$V$10 -> #VALUE! | W22: =$N22*$W$10 -> #VALUE! | X22: =$N22*$X$10 -> #VALUE! | Y22: =$N22*$Y$10 -> #VALUE! | Z22: =$N22*$Z$10 -> #VALUE! | AA22: =$N22*$AA$10 -> #VALUE! | AB22: =$N22*$AB$10 -> #VALUE! | AC22: =$N22*$AC$10 -> #VALUE! | AD22: =$N22*$AD$10 -> #VALUE! | AE22: =$N22*$AE$10 -> #VALUE! | AF22: =$N22*$AF$10 -> #VALUE! | AG22: =$N22*$AG$10 -> #VALUE! | AH22: =$N22*$AH$10 -> #VALUE! | AI22: =$N22*$AI$10 -> #VALUE! | AJ22: =$N22*$AJ$10 -> #VALUE! | AK22: =$N22*$AK$10 -> #VALUE! | AM22: 9000 | AU22: 6000 | AX22: =SUM(AM22:AW22) -> 15000
A23: =A22+1 -> 12 | G23: Không yêu cầu | J23: =IF(ISERROR(1000000*H23/$E$2),"",1000000*H23/$E$2) -> 0 | K23: =J23*$K$11*$N$9/1000000 -> 0 | L23: =J23*$L$11*$N$9/1000000 -> 0 | M23: =IF(I23<K23,"Cần order thêm",IF(I23>L23,"Quá nhiều hàng tồn","")) | N23: =IF(M23="Cần order thêm",L23-I23,"") | Q23: =$N23*$Q$10 -> #VALUE! | R23: =$N23*$R$10 -> #VALUE! | S23: =$N23*$S$10 -> #VALUE! | T23: =$N23*$T$10 -> #VALUE! | U23: =$N23*$U$10 -> #VALUE! | V23: =$N23*$V$10 -> #VALUE! | W23: =$N23*$W$10 -> #VALUE! | X23: =$N23*$X$10 -> #VALUE! | Y23: =$N23*$Y$10 -> #VALUE! | Z23: =$N23*$Z$10 -> #VALUE! | AA23: =$N23*$AA$10 -> #VALUE! | AB23: =$N23*$AB$10 -> #VALUE! | AC23: =$N23*$AC$10 -> #VALUE! | AD23: =$N23*$AD$10 -> #VALUE! | AE23: =$N23*$AE$10 -> #VALUE! | AF23: =$N23*$AF$10 -> #VALUE! | AG23: =$N23*$AG$10 -> #VALUE! | AH23: =$N23*$AH$10 -> #VALUE! | AI23: =$N23*$AI$10 -> #VALUE! | AJ23: =$N23*$AJ$10 -> #VALUE! | AK23: =$N23*$AK$10 -> #VALUE! | AM23: 230 | AU23: 150 | AX23: =SUM(AM23:AW23) -> 380
A24: =A23+1 -> 13 | G24: Không yêu cầu | J24: =IF(ISERROR(1000000*H24/$E$2),"",1000000*H24/$E$2) -> 0 | K24: =J24*$K$11*$N$9/1000000 -> 0 | L24: =J24*$L$11*$N$9/1000000 -> 0 | M24: =IF(I24<K24,"Cần order thêm",IF(I24>L24,"Quá nhiều hàng tồn","")) | N24: =IF(M24="Cần order thêm",L24-I24,"") | Q24: =$N24*$Q$10 -> #VALUE! | R24: =$N24*$R$10 -> #VALUE! | S24: =$N24*$S$10 -> #VALUE! | T24: =$N24*$T$10 -> #VALUE! | U24: =$N24*$U$10 -> #VALUE! | V24: =$N24*$V$10 -> #VALUE! | W24: =$N24*$W$10 -> #VALUE! | X24: =$N24*$X$10 -> #VALUE! | Y24: =$N24*$Y$10 -> #VALUE! | Z24: =$N24*$Z$10 -> #VALUE! | AA24: =$N24*$AA$10 -> #VALUE! | AB24: =$N24*$AB$10 -> #VALUE! | AC24: =$N24*$AC$10 -> #VALUE! | AD24: =$N24*$AD$10 -> #VALUE! | AE24: =$N24*$AE$10 -> #VALUE! | AF24: =$N24*$AF$10 -> #VALUE! | AG24: =$N24*$AG$10 -> #VALUE! | AH24: =$N24*$AH$10 -> #VALUE! | AI24: =$N24*$AI$10 -> #VALUE! | AJ24: =$N24*$AJ$10 -> #VALUE! | AK24: =$N24*$AK$10 -> #VALUE!
A25: =A24+1 -> 14 | G25: 30kg | J25: =IF(ISERROR(1000000*H25/$E$2),"",1000000*H25/$E$2) -> 0 | K25: =J25*$K$11*$N$9/1000000 -> 0 | L25: =J25*$L$11*$N$9/1000000 -> 0 | M25: =IF(I25<K25,"Cần order thêm",IF(I25>L25,"Quá nhiều hàng tồn","")) | N25: =IF(M25="Cần order thêm",L25-I25,"") | Q25: =$N25*$Q$10 -> #VALUE! | R25: =$N25*$R$10 -> #VALUE! | S25: =$N25*$S$10 -> #VALUE! | T25: =$N25*$T$10 -> #VALUE! | U25: =$N25*$U$10 -> #VALUE! | V25: =$N25*$V$10 -> #VALUE! | W25: =$N25*$W$10 -> #VALUE! | X25: =$N25*$X$10 -> #VALUE! | Y25: =$N25*$Y$10 -> #VALUE! | Z25: =$N25*$Z$10 -> #VALUE! | AA25: =$N25*$AA$10 -> #VALUE! | AB25: =$N25*$AB$10 -> #VALUE! | AC25: =$N25*$AC$10 -> #VALUE! | AD25: =$N25*$AD$10 -> #VALUE! | AE25: =$N25*$AE$10 -> #VALUE! | AF25: =$N25*$AF$10 -> #VALUE! | AG25: =$N25*$AG$10 -> #VALUE! | AH25: =$N25*$AH$10 -> #VALUE! | AI25: =$N25*$AI$10 -> #VALUE! | AJ25: =$N25*$AJ$10 -> #VALUE! | AK25: =$N25*$AK$10 -> #VALUE!
A26: =A25+1 -> 15 | G26: Không yêu cầu | J26: =IF(ISERROR(1000000*H26/$E$2),"",1000000*H26/$E$2) -> 0 | K26: =J26*$K$11*$N$9/1000000 -> 0 | L26: =J26*$L$11*$N$9/1000000 -> 0 | M26: =IF(I26<K26,"Cần order thêm",IF(I26>L26,"Quá nhiều hàng tồn","")) | N26: =IF(M26="Cần order thêm",L26-I26,"") | Q26: =$N26*$Q$10 -> #VALUE! | R26: =$N26*$R$10 -> #VALUE! | S26: =$N26*$S$10 -> #VALUE! | T26: =$N26*$T$10 -> #VALUE! | U26: =$N26*$U$10 -> #VALUE! | V26: =$N26*$V$10 -> #VALUE! | W26: =$N26*$W$10 -> #VALUE! | X26: =$N26*$X$10 -> #VALUE! | Y26: =$N26*$Y$10 -> #VALUE! | Z26: =$N26*$Z$10 -> #VALUE! | AA26: =$N26*$AA$10 -> #VALUE! | AB26: =$N26*$AB$10 -> #VALUE! | AC26: =$N26*$AC$10 -> #VALUE! | AD26: =$N26*$AD$10 -> #VALUE! | AE26: =$N26*$AE$10 -> #VALUE! | AF26: =$N26*$AF$10 -> #VALUE! | AG26: =$N26*$AG$10 -> #VALUE! | AH26: =$N26*$AH$10 -> #VALUE! | AI26: =$N26*$AI$10 -> #VALUE! | AJ26: =$N26*$AJ$10 -> #VALUE! | AK26: =$N26*$AK$10 -> #VALUE! | AM26: 312 | AU26: 192 | AX26: =SUM(AM26:AW26) -> 504
A27: =A26+1 -> 16 | G27: 24kg | J27: =IF(ISERROR(1000000*H27/$E$2),"",1000000*H27/$E$2) -> 0 | K27: =J27*$K$11*$N$9/1000000 -> 0 | L27: =J27*$L$11*$N$9/1000000 -> 0 | M27: =IF(I27<K27,"Cần order thêm",IF(I27>L27,"Quá nhiều hàng tồn","")) | N27: =IF(M27="Cần order thêm",L27-I27,"") | Q27: =$N27*$Q$10 -> #VALUE! | R27: =$N27*$R$10 -> #VALUE! | S27: =$N27*$S$10 -> #VALUE! | T27: =$N27*$T$10 -> #VALUE! | U27: =$N27*$U$10 -> #VALUE! | V27: =$N27*$V$10 -> #VALUE! | W27: =$N27*$W$10 -> #VALUE! | X27: =$N27*$X$10 -> #VALUE! | Y27: =$N27*$Y$10 -> #VALUE! | Z27: =$N27*$Z$10 -> #VALUE! | AA27: =$N27*$AA$10 -> #VALUE! | AB27: =$N27*$AB$10 -> #VALUE! | AC27: =$N27*$AC$10 -> #VALUE! | AD27: =$N27*$AD$10 -> #VALUE! | AE27: =$N27*$AE$10 -> #VALUE! | AF27: =$N27*$AF$10 -> #VALUE! | AG27: =$N27*$AG$10 -> #VALUE! | AH27: =$N27*$AH$10 -> #VALUE! | AI27: =$N27*$AI$10 -> #VALUE! | AJ27: =$N27*$AJ$10 -> #VALUE! | AK27: =$N27*$AK$10 -> #VALUE! | AM27: 60000 | AQ27: =4*12000 -> 48000 | AU27: 60000 | AX27: =SUM(AM27:AW27) -> 168000
A28: =A27+1 -> 17 | G28: 2 box | J28: =IF(ISERROR(1000000*H28/$E$2),"",1000000*H28/$E$2) -> 0 | K28: =J28*$K$11*$N$9/1000000 -> 0 | L28: =J28*$L$11*$N$9/1000000 -> 0 | M28: =IF(I28<K28,"Cần order thêm",IF(I28>L28,"Quá nhiều hàng tồn","")) | N28: =IF(M28="Cần order thêm",L28-I28,"") | Q28: =$N28*$Q$10 -> #VALUE! | R28: =$N28*$R$10 -> #VALUE! | S28: =$N28*$S$10 -> #VALUE! | T28: =$N28*$T$10 -> #VALUE! | U28: =$N28*$U$10 -> #VALUE! | V28: =$N28*$V$10 -> #VALUE! | W28: =$N28*$W$10 -> #VALUE! | X28: =$N28*$X$10 -> #VALUE! | Y28: =$N28*$Y$10 -> #VALUE! | Z28: =$N28*$Z$10 -> #VALUE! | AA28: =$N28*$AA$10 -> #VALUE! | AB28: =$N28*$AB$10 -> #VALUE! | AC28: =$N28*$AC$10 -> #VALUE! | AD28: =$N28*$AD$10 -> #VALUE! | AE28: =$N28*$AE$10 -> #VALUE! | AF28: =$N28*$AF$10 -> #VALUE! | AG28: =$N28*$AG$10 -> #VALUE! | AH28: =$N28*$AH$10 -> #VALUE! | AI28: =$N28*$AI$10 -> #VALUE! | AJ28: =$N28*$AJ$10 -> #VALUE! | AK28: =$N28*$AK$10 -> #VALUE!
A29: =A28+1 -> 18 | G29: 2 box | J29: =IF(ISERROR(1000000*H29/$E$2),"",1000000*H29/$E$2) -> 0 | K29: =J29*$K$11*$N$9/1000000 -> 0 | L29: =J29*$L$11*$N$9/1000000 -> 0 | M29: =IF(I29<K29,"Cần order thêm",IF(I29>L29,"Quá nhiều hàng tồn","")) | N29: =IF(M29="Cần order thêm",L29-I29,"") | Q29: =$N29*$Q$10 -> #VALUE! | R29: =$N29*$R$10 -> #VALUE! | S29: =$N29*$S$10 -> #VALUE! | T29: =$N29*$T$10 -> #VALUE! | U29: =$N29*$U$10 -> #VALUE! | V29: =$N29*$V$10 -> #VALUE! | W29: =$N29*$W$10 -> #VALUE! | X29: =$N29*$X$10 -> #VALUE! | Y29: =$N29*$Y$10 -> #VALUE! | Z29: =$N29*$Z$10 -> #VALUE! | AA29: =$N29*$AA$10 -> #VALUE! | AB29: =$N29*$AB$10 -> #VALUE! | AC29: =$N29*$AC$10 -> #VALUE! | AD29: =$N29*$AD$10 -> #VALUE! | AE29: =$N29*$AE$10 -> #VALUE! | AF29: =$N29*$AF$10 -> #VALUE! | AG29: =$N29*$AG$10 -> #VALUE! | AH29: =$N29*$AH$10 -> #VALUE! | AI29: =$N29*$AI$10 -> #VALUE! | AJ29: =$N29*$AJ$10 -> #VALUE! | AK29: =$N29*$AK$10 -> #VALUE!
A30: =A29+1 -> 19 | G30: 2 box | J30: =IF(ISERROR(1000000*H30/$E$2),"",1000000*H30/$E$2) -> 0 | K30: =J30*$K$11*$N$9/1000000 -> 0 | L30: =J30*$L$11*$N$9/1000000 -> 0 | M30: =IF(I30<K30,"Cần order thêm",IF(I30>L30,"Quá nhiều hàng tồn","")) | N30: =IF(M30="Cần order thêm",L30-I30,"") | Q30: =$N30*$Q$10 -> #VALUE! | R30: =$N30*$R$10 -> #VALUE! | S30: =$N30*$S$10 -> #VALUE! | T30: =$N30*$T$10 -> #VALUE! | U30: =$N30*$U$10 -> #VALUE! | V30: =$N30*$V$10 -> #VALUE! | W30: =$N30*$W$10 -> #VALUE! | X30: =$N30*$X$10 -> #VALUE! | Y30: =$N30*$Y$10 -> #VALUE! | Z30: =$N30*$Z$10 -> #VALUE! | AA30: =$N30*$AA$10 -> #VALUE! | AB30: =$N30*$AB$10 -> #VALUE! | AC30: =$N30*$AC$10 -> #VALUE! | AD30: =$N30*$AD$10 -> #VALUE! | AE30: =$N30*$AE$10 -> #VALUE! | AF30: =$N30*$AF$10 -> #VALUE! | AG30: =$N30*$AG$10 -> #VALUE! | AH30: =$N30*$AH$10 -> #VALUE! | AI30: =$N30*$AI$10 -> #VALUE! | AJ30: =$N30*$AJ$10 -> #VALUE! | AK30: =$N30*$AK$10 -> #VALUE!
A31: =A30+1 -> 20 | G31: Không yêu cầu | J31: =IF(ISERROR(1000000*H31/$E$2),"",1000000*H31/$E$2) -> 0 | K31: =J31*$K$11*$N$9/1000000 -> 0 | L31: =J31*$L$11*$N$9/1000000 -> 0 | M31: =IF(I31<K31,"Cần order thêm",IF(I31>L31,"Quá nhiều hàng tồn","")) | N31: =IF(M31="Cần order thêm",L31-I31,"") | Q31: =$N31*$Q$10 -> #VALUE! | R31: =$N31*$R$10 -> #VALUE! | S31: =$N31*$S$10 -> #VALUE! | T31: =$N31*$T$10 -> #VALUE! | U31: =$N31*$U$10 -> #VALUE! | V31: =$N31*$V$10 -> #VALUE! | W31: =$N31*$W$10 -> #VALUE! | X31: =$N31*$X$10 -> #VALUE! | Y31: =$N31*$Y$10 -> #VALUE! | Z31: =$N31*$Z$10 -> #VALUE! | AA31: =$N31*$AA$10 -> #VALUE! | AB31: =$N31*$AB$10 -> #VALUE! | AC31: =$N31*$AC$10 -> #VALUE! | AD31: =$N31*$AD$10 -> #VALUE! | AE31: =$N31*$AE$10 -> #VALUE! | AF31: =$N31*$AF$10 -> #VALUE! | AG31: =$N31*$AG$10 -> #VALUE! | AH31: =$N31*$AH$10 -> #VALUE! | AI31: =$N31*$AI$10 -> #VALUE! | AJ31: =$N31*$AJ$10 -> #VALUE! | AK31: =$N31*$AK$10 -> #VALUE! | AM31: 20000 | AQ31: 15000 | AU31: 15000 | AX31: =SUM(AM31:AW31) -> 50000
A32: =A31+1 -> 21 | G32: Không yêu cầu | J32: =IF(ISERROR(1000000*H32/$E$2),"",1000000*H32/$E$2) -> 0 | K32: =J32*$K$11*$N$9/1000000 -> 0 | L32: =J32*$L$11*$N$9/1000000 -> 0 | M32: =IF(I32<K32,"Cần order thêm",IF(I32>L32,"Quá nhiều hàng tồn","")) | N32: =IF(M32="Cần order thêm",L32-I32,"") | Q32: =$N32*$Q$10 -> #VALUE! | R32: =$N32*$R$10 -> #VALUE! | S32: =$N32*$S$10 -> #VALUE! | T32: =$N32*$T$10 -> #VALUE! | U32: =$N32*$U$10 -> #VALUE! | V32: =$N32*$V$10 -> #VALUE! | W32: =$N32*$W$10 -> #VALUE! | X32: =$N32*$X$10 -> #VALUE! | Y32: =$N32*$Y$10 -> #VALUE! | Z32: =$N32*$Z$10 -> #VALUE! | AA32: =$N32*$AA$10 -> #VALUE! | AB32: =$N32*$AB$10 -> #VALUE! | AC32: =$N32*$AC$10 -> #VALUE! | AD32: =$N32*$AD$10 -> #VALUE! | AE32: =$N32*$AE$10 -> #VALUE! | AF32: =$N32*$AF$10 -> #VALUE! | AG32: =$N32*$AG$10 -> #VALUE! | AH32: =$N32*$AH$10 -> #VALUE! | AI32: =$N32*$AI$10 -> #VALUE! | AJ32: =$N32*$AJ$10 -> #VALUE! | AK32: =$N32*$AK$10 -> #VALUE! | AM32: 30000 | AQ32: 30000 | AU32: 30000 | AX32: =SUM(AM32:AW32) -> 90000
A33: =A32+1 -> 22 | G33: 250000 | J33: =IF(ISERROR(1000000*H33/$E$2),"",1000000*H33/$E$2) -> 0 | K33: =J33*$K$11*$N$9/1000000 -> 0 | L33: =J33*$L$11*$N$9/1000000 -> 0 | M33: =IF(I33<K33,"Cần order thêm",IF(I33>L33,"Quá nhiều hàng tồn","")) | N33: =IF(M33="Cần order thêm",L33-I33,"") | Q33: =$N33*$Q$10 -> #VALUE! | R33: =$N33*$R$10 -> #VALUE! | S33: =$N33*$S$10 -> #VALUE! | T33: =$N33*$T$10 -> #VALUE! | U33: =$N33*$U$10 -> #VALUE! | V33: =$N33*$V$10 -> #VALUE! | W33: =$N33*$W$10 -> #VALUE! | X33: =$N33*$X$10 -> #VALUE! | Y33: =$N33*$Y$10 -> #VALUE! | Z33: =$N33*$Z$10 -> #VALUE! | AA33: =$N33*$AA$10 -> #VALUE! | AB33: =$N33*$AB$10 -> #VALUE! | AC33: =$N33*$AC$10 -> #VALUE! | AD33: =$N33*$AD$10 -> #VALUE! | AE33: =$N33*$AE$10 -> #VALUE! | AF33: =$N33*$AF$10 -> #VALUE! | AG33: =$N33*$AG$10 -> #VALUE! | AH33: =$N33*$AH$10 -> #VALUE! | AI33: =$N33*$AI$10 -> #VALUE! | AJ33: =$N33*$AJ$10 -> #VALUE! | AK33: =$N33*$AK$10 -> #VALUE! | AM33: 100 | AU33: 60 | AX33: =SUM(AM33:AW33) -> 160
A34: =A33+1 -> 23 | G34: 500000 | J34: =IF(ISERROR(1000000*H34/$E$2),"",1000000*H34/$E$2) -> 0 | K34: =J34*$K$11*$N$9/1000000 -> 0 | L34: =J34*$L$11*$N$9/1000000 -> 0 | M34: =IF(I34<K34,"Cần order thêm",IF(I34>L34,"Quá nhiều hàng tồn","")) | N34: =IF(M34="Cần order thêm",L34-I34,"") | Q34: =$N34*$Q$10 -> #VALUE! | R34: =$N34*$R$10 -> #VALUE! | S34: =$N34*$S$10 -> #VALUE! | T34: =$N34*$T$10 -> #VALUE! | U34: =$N34*$U$10 -> #VALUE! | V34: =$N34*$V$10 -> #VALUE! | W34: =$N34*$W$10 -> #VALUE! | X34: =$N34*$X$10 -> #VALUE! | Y34: =$N34*$Y$10 -> #VALUE! | Z34: =$N34*$Z$10 -> #VALUE! | AA34: =$N34*$AA$10 -> #VALUE! | AB34: =$N34*$AB$10 -> #VALUE! | AC34: =$N34*$AC$10 -> #VALUE! | AD34: =$N34*$AD$10 -> #VALUE! | AE34: =$N34*$AE$10 -> #VALUE! | AF34: =$N34*$AF$10 -> #VALUE! | AG34: =$N34*$AG$10 -> #VALUE! | AH34: =$N34*$AH$10 -> #VALUE! | AI34: =$N34*$AI$10 -> #VALUE! | AJ34: =$N34*$AJ$10 -> #VALUE! | AK34: =$N34*$AK$10 -> #VALUE!
A35: =A34+1 -> 24 | G35: 10 kg | J35: =IF(ISERROR(1000000*H35/$E$2),"",1000000*H35/$E$2) -> 0 | K35: =J35*$K$11*$N$9/1000000 -> 0 | L35: =J35*$L$11*$N$9/1000000 -> 0 | M35: =IF(I35<K35,"Cần order thêm",IF(I35>L35,"Quá nhiều hàng tồn","")) | N35: =IF(M35="Cần order thêm",L35-I35,"") | Q35: =$N35*$Q$10 -> #VALUE! | R35: =$N35*$R$10 -> #VALUE! | S35: =$N35*$S$10 -> #VALUE! | T35: =$N35*$T$10 -> #VALUE! | U35: =$N35*$U$10 -> #VALUE! | V35: =$N35*$V$10 -> #VALUE! | W35: =$N35*$W$10 -> #VALUE! | X35: =$N35*$X$10 -> #VALUE! | Y35: =$N35*$Y$10 -> #VALUE! | Z35: =$N35*$Z$10 -> #VALUE! | AA35: =$N35*$AA$10 -> #VALUE! | AB35: =$N35*$AB$10 -> #VALUE! | AC35: =$N35*$AC$10 -> #VALUE! | AD35: =$N35*$AD$10 -> #VALUE! | AE35: =$N35*$AE$10 -> #VALUE! | AF35: =$N35*$AF$10 -> #VALUE! | AG35: =$N35*$AG$10 -> #VALUE! | AH35: =$N35*$AH$10 -> #VALUE! | AI35: =$N35*$AI$10 -> #VALUE! | AJ35: =$N35*$AJ$10 -> #VALUE! | AK35: =$N35*$AK$10 -> #VALUE!
A36: =A35+1 -> 25 | G36: 500000 | J36: =IF(ISERROR(1000000*H36/$E$2),"",1000000*H36/$E$2) -> 0 | K36: =J36*$K$11*$N$9/1000000 -> 0 | L36: =J36*$L$11*$N$9/1000000 -> 0 | M36: =IF(I36<K36,"Cần order thêm",IF(I36>L36,"Quá nhiều hàng tồn","")) | N36: =IF(M36="Cần order thêm",L36-I36,"") | Q36: =$N36*$Q$10 -> #VALUE! | R36: =$N36*$R$10 -> #VALUE! | S36: =$N36*$S$10 -> #VALUE! | T36: =$N36*$T$10 -> #VALUE! | U36: =$N36*$U$10 -> #VALUE! | V36: =$N36*$V$10 -> #VALUE! | W36: =$N36*$W$10 -> #VALUE! | X36: =$N36*$X$10 -> #VALUE! | Y36: =$N36*$Y$10 -> #VALUE! | Z36: =$N36*$Z$10 -> #VALUE! | AA36: =$N36*$AA$10 -> #VALUE! | AB36: =$N36*$AB$10 -> #VALUE! | AC36: =$N36*$AC$10 -> #VALUE! | AD36: =$N36*$AD$10 -> #VALUE! | AE36: =$N36*$AE$10 -> #VALUE! | AF36: =$N36*$AF$10 -> #VALUE! | AG36: =$N36*$AG$10 -> #VALUE! | AH36: =$N36*$AH$10 -> #VALUE! | AI36: =$N36*$AI$10 -> #VALUE! | AJ36: =$N36*$AJ$10 -> #VALUE! | AK36: =$N36*$AK$10 -> #VALUE!
A37: =A36+1 -> 26 | G37: 500000 | J37: =IF(ISERROR(1000000*H37/$E$2),"",1000000*H37/$E$2) -> 0 | K37: =J37*$K$11*$N$9/1000000 -> 0 | L37: =J37*$L$11*$N$9/1000000 -> 0 | M37: =IF(I37<K37,"Cần order thêm",IF(I37>L37,"Quá nhiều hàng tồn","")) | N37: =IF(M37="Cần order thêm",L37-I37,"") | Q37: =$N37*$Q$10 -> #VALUE! | R37: =$N37*$R$10 -> #VALUE! | S37: =$N37*$S$10 -> #VALUE! | T37: =$N37*$T$10 -> #VALUE! | U37: =$N37*$U$10 -> #VALUE! | V37: =$N37*$V$10 -> #VALUE! | W37: =$N37*$W$10 -> #VALUE! | X37: =$N37*$X$10 -> #VALUE! | Y37: =$N37*$Y$10 -> #VALUE! | Z37: =$N37*$Z$10 -> #VALUE! | AA37: =$N37*$AA$10 -> #VALUE! | AB37: =$N37*$AB$10 -> #VALUE! | AC37: =$N37*$AC$10 -> #VALUE! | AD37: =$N37*$AD$10 -> #VALUE! | AE37: =$N37*$AE$10 -> #VALUE! | AF37: =$N37*$AF$10 -> #VALUE! | AG37: =$N37*$AG$10 -> #VALUE! | AH37: =$N37*$AH$10 -> #VALUE! | AI37: =$N37*$AI$10 -> #VALUE! | AJ37: =$N37*$AJ$10 -> #VALUE! | AK37: =$N37*$AK$10 -> #VALUE!
A38: =A37+1 -> 27 | G38: 500000 | J38: =IF(ISERROR(1000000*H38/$E$2),"",1000000*H38/$E$2) -> 0 | K38: =J38*$K$11*$N$9/1000000 -> 0 | L38: =J38*$L$11*$N$9/1000000 -> 0 | M38: =IF(I38<K38,"Cần order thêm",IF(I38>L38,"Quá nhiều hàng tồn","")) | N38: =IF(M38="Cần order thêm",L38-I38,"") | Q38: =$N38*$Q$10 -> #VALUE! | R38: =$N38*$R$10 -> #VALUE! | S38: =$N38*$S$10 -> #VALUE! | T38: =$N38*$T$10 -> #VALUE! | U38: =$N38*$U$10 -> #VALUE! | V38: =$N38*$V$10 -> #VALUE! | W38: =$N38*$W$10 -> #VALUE! | X38: =$N38*$X$10 -> #VALUE! | Y38: =$N38*$Y$10 -> #VALUE! | Z38: =$N38*$Z$10 -> #VALUE! | AA38: =$N38*$AA$10 -> #VALUE! | AB38: =$N38*$AB$10 -> #VALUE! | AC38: =$N38*$AC$10 -> #VALUE! | AD38: =$N38*$AD$10 -> #VALUE! | AE38: =$N38*$AE$10 -> #VALUE! | AF38: =$N38*$AF$10 -> #VALUE! | AG38: =$N38*$AG$10 -> #VALUE! | AH38: =$N38*$AH$10 -> #VALUE! | AI38: =$N38*$AI$10 -> #VALUE! | AJ38: =$N38*$AJ$10 -> #VALUE! | AK38: =$N38*$AK$10 -> #VALUE!
A39: =A38+1 -> 28 | G39: 500000 | J39: =IF(ISERROR(1000000*H39/$E$2),"",1000000*H39/$E$2) -> 0 | K39: =J39*$K$11*$N$9/1000000 -> 0 | L39: =J39*$L$11*$N$9/1000000 -> 0 | M39: =IF(I39<K39,"Cần order thêm",IF(I39>L39,"Quá nhiều hàng tồn","")) | N39: =IF(M39="Cần order thêm",L39-I39,"") | Q39: =$N39*$Q$10 -> #VALUE! | R39: =$N39*$R$10 -> #VALUE! | S39: =$N39*$S$10 -> #VALUE! | T39: =$N39*$T$10 -> #VALUE! | U39: =$N39*$U$10 -> #VALUE! | V39: =$N39*$V$10 -> #VALUE! | W39: =$N39*$W$10 -> #VALUE! | X39: =$N39*$X$10 -> #VALUE! | Y39: =$N39*$Y$10 -> #VALUE! | Z39: =$N39*$Z$10 -> #VALUE! | AA39: =$N39*$AA$10 -> #VALUE! | AB39: =$N39*$AB$10 -> #VALUE! | AC39: =$N39*$AC$10 -> #VALUE! | AD39: =$N39*$AD$10 -> #VALUE! | AE39: =$N39*$AE$10 -> #VALUE! | AF39: =$N39*$AF$10 -> #VALUE! | AG39: =$N39*$AG$10 -> #VALUE! | AH39: =$N39*$AH$10 -> #VALUE! | AI39: =$N39*$AI$10 -> #VALUE! | AJ39: =$N39*$AJ$10 -> #VALUE! | AK39: =$N39*$AK$10 -> #VALUE!
A40: =A39+1 -> 29 | G40: 500000 | J40: =IF(ISERROR(1000000*H40/$E$2),"",1000000*H40/$E$2) -> 0 | K40: =J40*$K$11*$N$9/1000000 -> 0 | L40: =J40*$L$11*$N$9/1000000 -> 0 | M40: =IF(I40<K40,"Cần order thêm",IF(I40>L40,"Quá nhiều hàng tồn","")) | N40: =IF(M40="Cần order thêm",L40-I40,"") | Q40: =$N40*$Q$10 -> #VALUE! | R40: =$N40*$R$10 -> #VALUE! | S40: =$N40*$S$10 -> #VALUE! | T40: =$N40*$T$10 -> #VALUE! | U40: =$N40*$U$10 -> #VALUE! | V40: =$N40*$V$10 -> #VALUE! | W40: =$N40*$W$10 -> #VALUE! | X40: =$N40*$X$10 -> #VALUE! | Y40: =$N40*$Y$10 -> #VALUE! | Z40: =$N40*$Z$10 -> #VALUE! | AA40: =$N40*$AA$10 -> #VALUE! | AB40: =$N40*$AB$10 -> #VALUE! | AC40: =$N40*$AC$10 -> #VALUE! | AD40: =$N40*$AD$10 -> #VALUE! | AE40: =$N40*$AE$10 -> #VALUE! | AF40: =$N40*$AF$10 -> #VALUE! | AG40: =$N40*$AG$10 -> #VALUE! | AH40: =$N40*$AH$10 -> #VALUE! | AI40: =$N40*$AI$10 -> #VALUE! | AJ40: =$N40*$AJ$10 -> #VALUE! | AK40: =$N40*$AK$10 -> #VALUE!
A41: =A40+1 -> 30 | G41: 24 btl | J41: =IF(ISERROR(1000000*H41/$E$2),"",1000000*H41/$E$2) -> 0 | K41: =J41*$K$11*$N$9/1000000 -> 0 | L41: =J41*$L$11*$N$9/1000000 -> 0 | M41: =IF(I41<K41,"Cần order thêm",IF(I41>L41,"Quá nhiều hàng tồn","")) | N41: =IF(M41="Cần order thêm",L41-I41,"") | Q41: =$N41*$Q$10 -> #VALUE! | R41: =$N41*$R$10 -> #VALUE! | S41: =$N41*$S$10 -> #VALUE! | T41: =$N41*$T$10 -> #VALUE! | U41: =$N41*$U$10 -> #VALUE! | V41: =$N41*$V$10 -> #VALUE! | W41: =$N41*$W$10 -> #VALUE! | X41: =$N41*$X$10 -> #VALUE! | Y41: =$N41*$Y$10 -> #VALUE! | Z41: =$N41*$Z$10 -> #VALUE! | AA41: =$N41*$AA$10 -> #VALUE! | AB41: =$N41*$AB$10 -> #VALUE! | AC41: =$N41*$AC$10 -> #VALUE! | AD41: =$N41*$AD$10 -> #VALUE! | AE41: =$N41*$AE$10 -> #VALUE! | AF41: =$N41*$AF$10 -> #VALUE! | AG41: =$N41*$AG$10 -> #VALUE! | AH41: =$N41*$AH$10 -> #VALUE! | AI41: =$N41*$AI$10 -> #VALUE! | AJ41: =$N41*$AJ$10 -> #VALUE! | AK41: =$N41*$AK$10 -> #VALUE!
A42: =A41+1 -> 31 | G42: Không yêu cầu | J42: =IF(ISERROR(1000000*H42/$E$2),"",1000000*H42/$E$2) -> 0 | K42: =J42*$K$11*$N$9/1000000 -> 0 | L42: =J42*$L$11*$N$9/1000000 -> 0 | M42: =IF(I42<K42,"Cần order thêm",IF(I42>L42,"Quá nhiều hàng tồn","")) | N42: =IF(M42="Cần order thêm",L42-I42,"") | Q42: =$N42*$Q$10 -> #VALUE! | R42: =$N42*$R$10 -> #VALUE! | S42: =$N42*$S$10 -> #VALUE! | T42: =$N42*$T$10 -> #VALUE! | U42: =$N42*$U$10 -> #VALUE! | V42: =$N42*$V$10 -> #VALUE! | W42: =$N42*$W$10 -> #VALUE! | X42: =$N42*$X$10 -> #VALUE! | Y42: =$N42*$Y$10 -> #VALUE! | Z42: =$N42*$Z$10 -> #VALUE! | AA42: =$N42*$AA$10 -> #VALUE! | AB42: =$N42*$AB$10 -> #VALUE! | AC42: =$N42*$AC$10 -> #VALUE! | AD42: =$N42*$AD$10 -> #VALUE! | AE42: =$N42*$AE$10 -> #VALUE! | AF42: =$N42*$AF$10 -> #VALUE! | AG42: =$N42*$AG$10 -> #VALUE! | AH42: =$N42*$AH$10 -> #VALUE! | AI42: =$N42*$AI$10 -> #VALUE! | AJ42: =$N42*$AJ$10 -> #VALUE! | AK42: =$N42*$AK$10 -> #VALUE! | AM42: 4000 | AO42: 4000 | AS42: 4000 | AW42: 4000 | AX42: =SUM(AM42:AW42) -> 16000
A43: =A42+1 -> 32 | G43: Không yêu cầu | J43: =IF(ISERROR(1000000*H43/$E$2),"",1000000*H43/$E$2) -> 0 | K43: =J43*$K$11*$N$9/1000000 -> 0 | L43: =J43*$L$11*$N$9/1000000 -> 0 | M43: =IF(I43<K43,"Cần order thêm",IF(I43>L43,"Quá nhiều hàng tồn","")) | N43: =IF(M43="Cần order thêm",L43-I43,"") | Q43: =$N43*$Q$10 -> #VALUE! | R43: =$N43*$R$10 -> #VALUE! | S43: =$N43*$S$10 -> #VALUE! | T43: =$N43*$T$10 -> #VALUE! | U43: =$N43*$U$10 -> #VALUE! | V43: =$N43*$V$10 -> #VALUE! | W43: =$N43*$W$10 -> #VALUE! | X43: =$N43*$X$10 -> #VALUE! | Y43: =$N43*$Y$10 -> #VALUE! | Z43: =$N43*$Z$10 -> #VALUE! | AA43: =$N43*$AA$10 -> #VALUE! | AB43: =$N43*$AB$10 -> #VALUE! | AC43: =$N43*$AC$10 -> #VALUE! | AD43: =$N43*$AD$10 -> #VALUE! | AE43: =$N43*$AE$10 -> #VALUE! | AF43: =$N43*$AF$10 -> #VALUE! | AG43: =$N43*$AG$10 -> #VALUE! | AH43: =$N43*$AH$10 -> #VALUE! | AI43: =$N43*$AI$10 -> #VALUE! | AJ43: =$N43*$AJ$10 -> #VALUE! | AK43: =$N43*$AK$10 -> #VALUE! | AM43: 10000 | AS43: 10000 | AW43: 10000 | AX43: =SUM(AM43:AW43) -> 30000
...

Sheet ĐƠN COOP
A2: DOANH THU THÁNG | E2: ='ĐƠN RAU'!E2 -> 10000000 | H2: CÔNG TY TNHH KIDO EDU
H4: Trường : | I4: KIDO | Q4: Weekly Sales Trend | AM4: NCC/CK | AO4: CK | AQ4: CK | AS4: CK | AU4: NCC | AW4: CK
F6: Kế hoạch đặt hàng hóa trong Tháng | Q6: 35000000 | R6: 35000000 | X6: 30000000 | Y6: 30000000 | Z6: 30000000 | AA6: 45000000 | AB6: 45000000 | AC6: 70000000 | AD6: 70000000 | AE6: 70000000 | AF6: 60000000 | AG6: 40000000 | AH6: 40000000 | AI6: 60000000 | AJ6: 60000000 | AK6: 50000000 | AM6: 28 TET | AO6: MUNG 2 | AQ6: MUNG 3 | AS6: MUNG 5 | AU6: MUNG 6 | AW6: MUNG 9
Q7: PHÂN BỔ SỐ LƯỢNG HÀNG NHẬP TRONG TUẦN | AM7: D1 | AO7: D2 | AQ7: D' | AS7: D3 | AU7: D2 | AW7: D4
X8: 27 Tết | Y8: 28 Tết | Z8: 29 Tết | AA8: 30 Tết | AB8: Mùng 1 | AC8: Mùng 2 | AD8: Mùng 3 | AE8: Mùng 4 | AF8: Mùng 5 | AG8: Mùng 6 | AH8: Mùng 7 | AI8: Mùng 8 | AJ8: Mùng 9 | AK8: Mùng 10 | AQ8: HANG NHAP GUI TAI CK
A9: STT | B9: NHÓM | C9: TÊN NHÀ CUNG CẤP | D9: CODE POS | E9: TÊN HÀNG | F9: ĐVT | G9: MOQ | H9: Số xuất dùng của tháng theo doanh thu | I9: Tồn Kiểm Kê | J9: Plan Sales cho thời gian nhập hàng tới: | N9: ='FC SALE'!D15 -> 33000000 | O9: Số cần đặt sau điều chỉnh ( nhập PM ) | Q9: 44228 | R9: =Q9+1 -> 44229 | S9: =R9+1 -> 44230 | T9: =S9+1 -> 44231 | U9: =T9+1 -> 44232 | V9: =U9+1 -> 44233 | W9: =V9+1 -> 44234 | X9: =W9+1 -> 44235 | Y9: =X9+1 -> 44236 | ... AK9: =AJ9+1 -> 44248 | AZ9: Số cần đặt sau điều chỉnh
J10: Usage per Mil | K10: Min | L10: Max | M10: Báo động | N10: Số cần đặt thêm | Q10: =Q6/$N$9 -> 1.0606061 | R10: =R6/$N$9 -> 1.0606061 | S10: =S6/$N$9 -> 0 | T10: =T6/$N$9 -> 0 | U10: =U6/$N$9 -> 0 | V10: =V6/$N$9 -> 0 | W10: =W6/$N$9 -> 0 | X10: =X6/$N$9 -> 0.90909091 | ... AK10: =AK6/$N$9 -> 1.5151515
K11: 1.2 | L11: 1.5
A12: 1 | H12: 3 | I12: 10 | J12: =IF(ISERROR(1000000*H12/$E$2),"",1000000*H12/$E$2) -> 0.3 | K12: =J12*$K$11*$N$9/1000000 -> 11.88 | L12: =J12*$L$11*$N$9/1000000 -> 14.85 | M12: =IF(I12<K12,"Cần order thêm",IF(I12>L12,"Quá nhiều hàng tồn","")) -> Cần order thêm | N12: =IF(M12="Cần order thêm",L12-I12,"") -> 4.85 | Q12: =$N12*$Q$10 -> 5.1439394 | R12: =$N12*$R$10 -> 5.1439394 | S12: =$N12*$S$10 -> 0 | T12: =$N12*$T$10 -> 0 | U12: =$N12*$U$10 -> 0 | V12: =$N12*$V$10 -> 0 | W12: =$N12*$W$10 -> 0 | X12: =$N12*$X$10 -> 4.4090909 | Y12: =$N12*$Y$10 -> 4.4090909 | Z12: =$N12*$Z$10 -> 4.4090909 | AA12: =$N12*$AA$10 -> 6.6136364 | AB12: =$N12*$AB$10 -> 6.6136364 | AC12: =$N12*$AC$10 -> 10.287879 | AD12: =$N12*$AD$10 -> 10.287879 | AE12: =$N12*$AE$10 -> 10.287879 | AF12: =$N12*$AF$10 -> 8.8181818 | AG12: =$N12*$AG$10 -> 5.8787879 | AH12: =$N12*$AH$10 -> 5.8787879 | AI12: =$N12*$AI$10 -> 8.8181818 | AJ12: =$N12*$AJ$10 -> 8.8181818 | AK12: =$N12*$AK$10 -> 7.3484848
A13: =A12+1 -> 2 | J13: =IF(ISERROR(1000000*H13/$E$2),"",1000000*H13/$E$2) -> 0 | K13: =J13*$K$11*$N$9/1000000 -> 0 | L13: =J13*$L$11*$N$9/1000000 -> 0 | M13: =IF(I13<K13,"Cần order thêm",IF(I13>L13,"Quá nhiều hàng tồn","")) | Q13: =$N13*$Q$10 -> 0 | R13: =$N13*$R$10 -> 0 | S13: =$N13*$S$10 -> 0 | T13: =$N13*$T$10 -> 0 | U13: =$N13*$U$10 -> 0 | V13: =$N13*$V$10 -> 0 | W13: =$N13*$W$10 -> 0 | X13: =$N13*$X$10 -> 0 | Y13: =$N13*$Y$10 -> 0 | Z13: =$N13*$Z$10 -> 0 | AA13: =$N13*$AA$10 -> 0 | AB13: =$N13*$AB$10 -> 0 | AC13: =$N13*$AC$10 -> 0 | AD13: =$N13*$AD$10 -> 0 | AE13: =$N13*$AE$10 -> 0 | AF13: =$N13*$AF$10 -> 0 | AG13: =$N13*$AG$10 -> 0 | AH13: =$N13*$AH$10 -> 0 | AI13: =$N13*$AI$10 -> 0 | AJ13: =$N13*$AJ$10 -> 0 | AK13: =$N13*$AK$10 -> 0
A14: =A13+1 -> 3 | J14: =IF(ISERROR(1000000*H14/$E$2),"",1000000*H14/$E$2) -> 0 | K14: =J14*$K$11*$N$9/1000000 -> 0 | L14: =J14*$L$11*$N$9/1000000 -> 0 | M14: =IF(I14<K14,"Cần order thêm",IF(I14>L14,"Quá nhiều hàng tồn","")) | Q14: =$N14*$Q$10 -> 0 | R14: =$N14*$R$10 -> 0 | S14: =$N14*$S$10 -> 0 | T14: =$N14*$T$10 -> 0 | U14: =$N14*$U$10 -> 0 | V14: =$N14*$V$10 -> 0 | W14: =$N14*$W$10 -> 0 | X14: =$N14*$X$10 -> 0 | Y14: =$N14*$Y$10 -> 0 | Z14: =$N14*$Z$10 -> 0 | AA14: =$N14*$AA$10 -> 0 | AB14: =$N14*$AB$10 -> 0 | AC14: =$N14*$AC$10 -> 0 | AD14: =$N14*$AD$10 -> 0 | AE14: =$N14*$AE$10 -> 0 | AF14: =$N14*$AF$10 -> 0 | AG14: =$N14*$AG$10 -> 0 | AH14: =$N14*$AH$10 -> 0 | AI14: =$N14*$AI$10 -> 0 | AJ14: =$N14*$AJ$10 -> 0 | AK14: =$N14*$AK$10 -> 0
A15: =A14+1 -> 4 | J15: =IF(ISERROR(1000000*H15/$E$2),"",1000000*H15/$E$2) -> 0 | K15: =J15*$K$11*$N$9/1000000 -> 0 | L15: =J15*$L$11*$N$9/1000000 -> 0 | M15: =IF(I15<K15,"Cần order thêm",IF(I15>L15,"Quá nhiều hàng tồn","")) | Q15: =$N15*$Q$10 -> 0 | R15: =$N15*$R$10 -> 0 | S15: =$N15*$S$10 -> 0 | T15: =$N15*$T$10 -> 0 | U15: =$N15*$U$10 -> 0 | V15: =$N15*$V$10 -> 0 | W15: =$N15*$W$10 -> 0 | X15: =$N15*$X$10 -> 0 | Y15: =$N15*$Y$10 -> 0 | Z15: =$N15*$Z$10 -> 0 | AA15: =$N15*$AA$10 -> 0 | AB15: =$N15*$AB$10 -> 0 | AC15: =$N15*$AC$10 -> 0 | AD15: =$N15*$AD$10 -> 0 | AE15: =$N15*$AE$10 -> 0 | AF15: =$N15*$AF$10 -> 0 | AG15: =$N15*$AG$10 -> 0 | AH15: =$N15*$AH$10 -> 0 | AI15: =$N15*$AI$10 -> 0 | AJ15: =$N15*$AJ$10 -> 0 | AK15: =$N15*$AK$10 -> 0
A16: =A15+1 -> 5 | J16: =IF(ISERROR(1000000*H16/$E$2),"",1000000*H16/$E$2) -> 0 | K16: =J16*$K$11*$N$9/1000000 -> 0 | L16: =J16*$L$11*$N$9/1000000 -> 0 | M16: =IF(I16<K16,"Cần order thêm",IF(I16>L16,"Quá nhiều hàng tồn","")) | Q16: =$N16*$Q$10 -> 0 | R16: =$N16*$R$10 -> 0 | S16: =$N16*$S$10 -> 0 | T16: =$N16*$T$10 -> 0 | U16: =$N16*$U$10 -> 0 | V16: =$N16*$V$10 -> 0 | W16: =$N16*$W$10 -> 0 | X16: =$N16*$X$10 -> 0 | Y16: =$N16*$Y$10 -> 0 | Z16: =$N16*$Z$10 -> 0 | AA16: =$N16*$AA$10 -> 0 | AB16: =$N16*$AB$10 -> 0 | AC16: =$N16*$AC$10 -> 0 | AD16: =$N16*$AD$10 -> 0 | AE16: =$N16*$AE$10 -> 0 | AF16: =$N16*$AF$10 -> 0 | AG16: =$N16*$AG$10 -> 0 | AH16: =$N16*$AH$10 -> 0 | AI16: =$N16*$AI$10 -> 0 | AJ16: =$N16*$AJ$10 -> 0 | AK16: =$N16*$AK$10 -> 0
A17: =A16+1 -> 6 | B17: Bev | C17: Công ty TNHH Thương Mại NH & KH | G17: 500000 | J17: =IF(ISERROR(1000000*H17/$E$2),"",1000000*H17/$E$2) -> 0 | K17: =J17*$K$11*$N$9/1000000 -> 0 | L17: =J17*$L$11*$N$9/1000000 -> 0 | M17: =IF(I17<K17,"Cần order thêm",IF(I17>L17,"Quá nhiều hàng tồn","")) | N17: =IF(M17="Cần order thêm",L17-I17,"") | Q17: =$N17*$Q$10 -> #VALUE! | R17: =$N17*$R$10 -> #VALUE! | S17: =$N17*$S$10 -> #VALUE! | T17: =$N17*$T$10 -> #VALUE! | U17: =$N17*$U$10 -> #VALUE! | V17: =$N17*$V$10 -> #VALUE! | W17: =$N17*$W$10 -> #VALUE! | X17: =$N17*$X$10 -> #VALUE! | Y17: =$N17*$Y$10 -> #VALUE! | Z17: =$N17*$Z$10 -> #VALUE! | AA17: =$N17*$AA$10 -> #VALUE! | AB17: =$N17*$AB$10 -> #VALUE! | AC17: =$N17*$AC$10 -> #VALUE! | AD17: =$N17*$AD$10 -> #VALUE! | AE17: =$N17*$AE$10 -> #VALUE! | AF17: =$N17*$AF$10 -> #VALUE! | AG17: =$N17*$AG$10 -> #VALUE! | AH17: =$N17*$AH$10 -> #VALUE! | AI17: =$N17*$AI$10 -> #VALUE! | AJ17: =$N17*$AJ$10 -> #VALUE! | AK17: =$N17*$AK$10 -> #VALUE!
A18: =A17+1 -> 7 | B18: Bev | C18: Công ty TNHH Thương Mại Và Dịch Vụ Lục Thủy Sài Gòn | G18: 2 Btl | J18: =IF(ISERROR(1000000*H18/$E$2),"",1000000*H18/$E$2) -> 0 | K18: =J18*$K$11*$N$9/1000000 -> 0 | L18: =J18*$L$11*$N$9/1000000 -> 0 | M18: =IF(I18<K18,"Cần order thêm",IF(I18>L18,"Quá nhiều hàng tồn","")) | N18: =IF(M18="Cần order thêm",L18-I18,"") | Q18: =$N18*$Q$10 -> #VALUE! | R18: =$N18*$R$10 -> #VALUE! | S18: =$N18*$S$10 -> #VALUE! | T18: =$N18*$T$10 -> #VALUE! | U18: =$N18*$U$10 -> #VALUE! | V18: =$N18*$V$10 -> #VALUE! | W18: =$N18*$W$10 -> #VALUE! | X18: =$N18*$X$10 -> #VALUE! | Y18: =$N18*$Y$10 -> #VALUE! | Z18: =$N18*$Z$10 -> #VALUE! | AA18: =$N18*$AA$10 -> #VALUE! | AB18: =$N18*$AB$10 -> #VALUE! | AC18: =$N18*$AC$10 -> #VALUE! | AD18: =$N18*$AD$10 -> #VALUE! | AE18: =$N18*$AE$10 -> #VALUE! | AF18: =$N18*$AF$10 -> #VALUE! | AG18: =$N18*$AG$10 -> #VALUE! | AH18: =$N18*$AH$10 -> #VALUE! | AI18: =$N18*$AI$10 -> #VALUE! | AJ18: =$N18*$AJ$10 -> #VALUE! | AK18: =$N18*$AK$10 -> #VALUE!
A19: =A18+1 -> 8 | B19: Other | C19: Công ty TNHH Sản Xuất và Thương Mại Hưng Long Phát | G19: Không yêu cầu | J19: =IF(ISERROR(1000000*H19/$E$2),"",1000000*H19/$E$2) -> 0 | K19: =J19*$K$11*$N$9/1000000 -> 0 | L19: =J19*$L$11*$N$9/1000000 -> 0 | M19: =IF(I19<K19,"Cần order thêm",IF(I19>L19,"Quá nhiều hàng tồn","")) | N19: =IF(M19="Cần order thêm",L19-I19,"") | Q19: =$N19*$Q$10 -> #VALUE! | R19: =$N19*$R$10 -> #VALUE! | S19: =$N19*$S$10 -> #VALUE! | T19: =$N19*$T$10 -> #VALUE! | U19: =$N19*$U$10 -> #VALUE! | V19: =$N19*$V$10 -> #VALUE! | W19: =$N19*$W$10 -> #VALUE! | X19: =$N19*$X$10 -> #VALUE! | Y19: =$N19*$Y$10 -> #VALUE! | Z19: =$N19*$Z$10 -> #VALUE! | AA19: =$N19*$AA$10 -> #VALUE! | AB19: =$N19*$AB$10 -> #VALUE! | AC19: =$N19*$AC$10 -> #VALUE! | AD19: =$N19*$AD$10 -> #VALUE! | AE19: =$N19*$AE$10 -> #VALUE! | AF19: =$N19*$AF$10 -> #VALUE! | AG19: =$N19*$AG$10 -> #VALUE! | AH19: =$N19*$AH$10 -> #VALUE! | AI19: =$N19*$AI$10 -> #VALUE! | AJ19: =$N19*$AJ$10 -> #VALUE! | AK19: =$N19*$AK$10 -> #VALUE!
A20: =A19+1 -> 9 | B20: Packaging | G20: 501 pcs | J20: =IF(ISERROR(1000000*H20/$E$2),"",1000000*H20/$E$2) -> 0 | K20: =J20*$K$11*$N$9/1000000 -> 0 | L20: =J20*$L$11*$N$9/1000000 -> 0 | M20: =IF(I20<K20,"Cần order thêm",IF(I20>L20,"Quá nhiều hàng tồn","")) | N20: =IF(M20="Cần order thêm",L20-I20,"") | Q20: =$N20*$Q$10 -> #VALUE! | R20: =$N20*$R$10 -> #VALUE! | S20: =$N20*$S$10 -> #VALUE! | T20: =$N20*$T$10 -> #VALUE! | U20: =$N20*$U$10 -> #VALUE! | V20: =$N20*$V$10 -> #VALUE! | W20: =$N20*$W$10 -> #VALUE! | X20: =$N20*$X$10 -> #VALUE! | Y20: =$N20*$Y$10 -> #VALUE! | Z20: =$N20*$Z$10 -> #VALUE! | AA20: =$N20*$AA$10 -> #VALUE! | AB20: =$N20*$AB$10 -> #VALUE! | AC20: =$N20*$AC$10 -> #VALUE! | AD20: =$N20*$AD$10 -> #VALUE! | AE20: =$N20*$AE$10 -> #VALUE! | AF20: =$N20*$AF$10 -> #VALUE! | AG20: =$N20*$AG$10 -> #VALUE! | AH20: =$N20*$AH$10 -> #VALUE! | AI20: =$N20*$AI$10 -> #VALUE! | AJ20: =$N20*$AJ$10 -> #VALUE! | AK20: =$N20*$AK$10 -> #VALUE!
A21: =A20+1 -> 10 | B21: Packaging | G21: 5000 psc | J21: =IF(ISERROR(1000000*H21/$E$2),"",1000000*H21/$E$2) -> 0 | K21: =J21*$K$11*$N$9/1000000 -> 0 | L21: =J21*$L$11*$N$9/1000000 -> 0 | M21: =IF(I21<K21,"Cần order thêm",IF(I21>L21,"Quá nhiều hàng tồn","")) | N21: =IF(M21="Cần order thêm",L21-I21,"") | Q21: =$N21*$Q$10 -> #VALUE! | R21: =$N21*$R$10 -> #VALUE! | S21: =$N21*$S$10 -> #VALUE! | T21: =$N21*$T$10 -> #VALUE! | U21: =$N21*$U$10 -> #VALUE! | V21: =$N21*$V$10 -> #VALUE! | W21: =$N21*$W$10 -> #VALUE! | X21: =$N21*$X$10 -> #VALUE! | Y21: =$N21*$Y$10 -> #VALUE! | Z21: =$N21*$Z$10 -> #VALUE! | AA21: =$N21*$AA$10 -> #VALUE! | AB21: =$N21*$AB$10 -> #VALUE! | AC21: =$N21*$AC$10 -> #VALUE! | AD21: =$N21*$AD$10 -> #VALUE! | AE21: =$N21*$AE$10 -> #VALUE! | AF21: =$N21*$AF$10 -> #VALUE! | AG21: =$N21*$AG$10 -> #VALUE! | AH21: =$N21*$AH$10 -> #VALUE! | AI21: =$N21*$AI$10 -> #VALUE! | AJ21: =$N21*$AJ$10 -> #VALUE! | AK21: =$N21*$AK$10 -> #VALUE!
A22: =A21+1 -> 11 | B22: Packaging | G22: 500 pcs | J22: =IF(ISERROR(1000000*H22/$E$2),"",1000000*H22/$E$2) -> 0 | K22: =J22*$K$11*$N$9/1000000 -> 0 | L22: =J22*$L$11*$N$9/1000000 -> 0 | M22: =IF(I22<K22,"Cần order thêm",IF(I22>L22,"Quá nhiều hàng tồn","")) | N22: =IF(M22="Cần order thêm",L22-I22,"") | Q22: =$N22*$Q$10 -> #VALUE! | R22: =$N22*$R$10 -> #VALUE! | S22: =$N22*$S$10 -> #VALUE! | T22: =$N22*$T$10 -> #VALUE! | U22: =$N22*$U$10 -> #VALUE! | V22: =$N22*$V$10 -> #VALUE! | W22: =$N22*$W$10 -> #VALUE! | X22: =$N22*$X$10 -> #VALUE! | Y22: =$N22*$Y$10 -> #VALUE! | Z22: =$N22*$Z$10 -> #VALUE! | AA22: =$N22*$AA$10 -> #VALUE! | AB22: =$N22*$AB$10 -> #VALUE! | AC22: =$N22*$AC$10 -> #VALUE! | AD22: =$N22*$AD$10 -> #VALUE! | AE22: =$N22*$AE$10 -> #VALUE! | AF22: =$N22*$AF$10 -> #VALUE! | AG22: =$N22*$AG$10 -> #VALUE! | AH22: =$N22*$AH$10 -> #VALUE! | AI22: =$N22*$AI$10 -> #VALUE! | AJ22: =$N22*$AJ$10 -> #VALUE! | AK22: =$N22*$AK$10 -> #VALUE!
A23: =A22+1 -> 12 | B23: Packaging | G23: 5000 psc | J23: =IF(ISERROR(1000000*H23/$E$2),"",1000000*H23/$E$2) -> 0 | K23: =J23*$K$11*$N$9/1000000 -> 0 | L23: =J23*$L$11*$N$9/1000000 -> 0 | M23: =IF(I23<K23,"Cần order thêm",IF(I23>L23,"Quá nhiều hàng tồn","")) | N23: =IF(M23="Cần order thêm",L23-I23,"") | Q23: =$N23*$Q$10 -> #VALUE! | R23: =$N23*$R$10 -> #VALUE! | S23: =$N23*$S$10 -> #VALUE! | T23: =$N23*$T$10 -> #VALUE! | U23: =$N23*$U$10 -> #VALUE! | V23: =$N23*$V$10 -> #VALUE! | W23: =$N23*$W$10 -> #VALUE! | X23: =$N23*$X$10 -> #VALUE! | Y23: =$N23*$Y$10 -> #VALUE! | Z23: =$N23*$Z$10 -> #VALUE! | AA23: =$N23*$AA$10 -> #VALUE! | AB23: =$N23*$AB$10 -> #VALUE! | AC23: =$N23*$AC$10 -> #VALUE! | AD23: =$N23*$AD$10 -> #VALUE! | AE23: =$N23*$AE$10 -> #VALUE! | AF23: =$N23*$AF$10 -> #VALUE! | AG23: =$N23*$AG$10 -> #VALUE! | AH23: =$N23*$AH$10 -> #VALUE! | AI23: =$N23*$AI$10 -> #VALUE! | AJ23: =$N23*$AJ$10 -> #VALUE! | AK23: =$N23*$AK$10 -> #VALUE!
A24: =A23+1 -> 13 | B24: Packaging | G24: 100 Pcs | J24: =IF(ISERROR(1000000*H24/$E$2),"",1000000*H24/$E$2) -> 0 | K24: =J24*$K$11*$N$9/1000000 -> 0 | L24: =J24*$L$11*$N$9/1000000 -> 0 | M24: =IF(I24<K24,"Cần order thêm",IF(I24>L24,"Quá nhiều hàng tồn","")) | N24: =IF(M24="Cần order thêm",L24-I24,"") | Q24: =$N24*$Q$10 -> #VALUE! | R24: =$N24*$R$10 -> #VALUE! | S24: =$N24*$S$10 -> #VALUE! | T24: =$N24*$T$10 -> #VALUE! | U24: =$N24*$U$10 -> #VALUE! | V24: =$N24*$V$10 -> #VALUE! | W24: =$N24*$W$10 -> #VALUE! | X24: =$N24*$X$10 -> #VALUE! | Y24: =$N24*$Y$10 -> #VALUE! | Z24: =$N24*$Z$10 -> #VALUE! | AA24: =$N24*$AA$10 -> #VALUE! | AB24: =$N24*$AB$10 -> #VALUE! | AC24: =$N24*$AC$10 -> #VALUE! | AD24: =$N24*$AD$10 -> #VALUE! | AE24: =$N24*$AE$10 -> #VALUE! | AF24: =$N24*$AF$10 -> #VALUE! | AG24: =$N24*$AG$10 -> #VALUE! | AH24: =$N24*$AH$10 -> #VALUE! | AI24: =$N24*$AI$10 -> #VALUE! | AJ24: =$N24*$AJ$10 -> #VALUE! | AK24: =$N24*$AK$10 -> #VALUE!
A25: =A24+1 -> 14 | B25: Packaging | G25: 500000 | J25: =IF(ISERROR(1000000*H25/$E$2),"",1000000*H25/$E$2) -> 0 | K25: =J25*$K$11*$N$9/1000000 -> 0 | L25: =J25*$L$11*$N$9/1000000 -> 0 | M25: =IF(I25<K25,"Cần order thêm",IF(I25>L25,"Quá nhiều hàng tồn","")) | N25: =IF(M25="Cần order thêm",L25-I25,"") | Q25: =$N25*$Q$10 -> #VALUE! | R25: =$N25*$R$10 -> #VALUE! | S25: =$N25*$S$10 -> #VALUE! | T25: =$N25*$T$10 -> #VALUE! | U25: =$N25*$U$10 -> #VALUE! | V25: =$N25*$V$10 -> #VALUE! | W25: =$N25*$W$10 -> #VALUE! | X25: =$N25*$X$10 -> #VALUE! | Y25: =$N25*$Y$10 -> #VALUE! | Z25: =$N25*$Z$10 -> #VALUE! | AA25: =$N25*$AA$10 -> #VALUE! | AB25: =$N25*$AB$10 -> #VALUE! | AC25: =$N25*$AC$10 -> #VALUE! | AD25: =$N25*$AD$10 -> #VALUE! | AE25: =$N25*$AE$10 -> #VALUE! | AF25: =$N25*$AF$10 -> #VALUE! | AG25: =$N25*$AG$10 -> #VALUE! | AH25: =$N25*$AH$10 -> #VALUE! | AI25: =$N25*$AI$10 -> #VALUE! | AJ25: =$N25*$AJ$10 -> #VALUE! | AK25: =$N25*$AK$10 -> #VALUE!
A26: =A25+1 -> 15 | B26: Packaging | G26: 500000 | J26: =IF(ISERROR(1000000*H26/$E$2),"",1000000*H26/$E$2) -> 0 | K26: =J26*$K$11*$N$9/1000000 -> 0 | L26: =J26*$L$11*$N$9/1000000 -> 0 | M26: =IF(I26<K26,"Cần order thêm",IF(I26>L26,"Quá nhiều hàng tồn","")) | N26: =IF(M26="Cần order thêm",L26-I26,"") | Q26: =$N26*$Q$10 -> #VALUE! | R26: =$N26*$R$10 -> #VALUE! | S26: =$N26*$S$10 -> #VALUE! | T26: =$N26*$T$10 -> #VALUE! | U26: =$N26*$U$10 -> #VALUE! | V26: =$N26*$V$10 -> #VALUE! | W26: =$N26*$W$10 -> #VALUE! | X26: =$N26*$X$10 -> #VALUE! | Y26: =$N26*$Y$10 -> #VALUE! | Z26: =$N26*$Z$10 -> #VALUE! | AA26: =$N26*$AA$10 -> #VALUE! | AB26: =$N26*$AB$10 -> #VALUE! | AC26: =$N26*$AC$10 -> #VALUE! | AD26: =$N26*$AD$10 -> #VALUE! | AE26: =$N26*$AE$10 -> #VALUE! | AF26: =$N26*$AF$10 -> #VALUE! | AG26: =$N26*$AG$10 -> #VALUE! | AH26: =$N26*$AH$10 -> #VALUE! | AI26: =$N26*$AI$10 -> #VALUE! | AJ26: =$N26*$AJ$10 -> #VALUE! | AK26: =$N26*$AK$10 -> #VALUE!
A27: =A26+1 -> 16 | B27: Packaging | G27: 500000 | J27: =IF(ISERROR(1000000*H27/$E$2),"",1000000*H27/$E$2) -> 0 | K27: =J27*$K$11*$N$9/1000000 -> 0 | L27: =J27*$L$11*$N$9/1000000 -> 0 | M27: =IF(I27<K27,"Cần order thêm",IF(I27>L27,"Quá nhiều hàng tồn","")) | N27: =IF(M27="Cần order thêm",L27-I27,"") | Q27: =$N27*$Q$10 -> #VALUE! | R27: =$N27*$R$10 -> #VALUE! | S27: =$N27*$S$10 -> #VALUE! | T27: =$N27*$T$10 -> #VALUE! | U27: =$N27*$U$10 -> #VALUE! | V27: =$N27*$V$10 -> #VALUE! | W27: =$N27*$W$10 -> #VALUE! | X27: =$N27*$X$10 -> #VALUE! | Y27: =$N27*$Y$10 -> #VALUE! | Z27: =$N27*$Z$10 -> #VALUE! | AA27: =$N27*$AA$10 -> #VALUE! | AB27: =$N27*$AB$10 -> #VALUE! | AC27: =$N27*$AC$10 -> #VALUE! | AD27: =$N27*$AD$10 -> #VALUE! | AE27: =$N27*$AE$10 -> #VALUE! | AF27: =$N27*$AF$10 -> #VALUE! | AG27: =$N27*$AG$10 -> #VALUE! | AH27: =$N27*$AH$10 -> #VALUE! | AI27: =$N27*$AI$10 -> #VALUE! | AJ27: =$N27*$AJ$10 -> #VALUE! | AK27: =$N27*$AK$10 -> #VALUE!
A28: =A27+1 -> 17 | B28: Packaging | G28: 5000 psc | J28: =IF(ISERROR(1000000*H28/$E$2),"",1000000*H28/$E$2) -> 0 | K28: =J28*$K$11*$N$9/1000000 -> 0 | L28: =J28*$L$11*$N$9/1000000 -> 0 | M28: =IF(I28<K28,"Cần order thêm",IF(I28>L28,"Quá nhiều hàng tồn","")) | N28: =IF(M28="Cần order thêm",L28-I28,"") | Q28: =$N28*$Q$10 -> #VALUE! | R28: =$N28*$R$10 -> #VALUE! | S28: =$N28*$S$10 -> #VALUE! | T28: =$N28*$T$10 -> #VALUE! | U28: =$N28*$U$10 -> #VALUE! | V28: =$N28*$V$10 -> #VALUE! | W28: =$N28*$W$10 -> #VALUE! | X28: =$N28*$X$10 -> #VALUE! | Y28: =$N28*$Y$10 -> #VALUE! | Z28: =$N28*$Z$10 -> #VALUE! | AA28: =$N28*$AA$10 -> #VALUE! | AB28: =$N28*$AB$10 -> #VALUE! | AC28: =$N28*$AC$10 -> #VALUE! | AD28: =$N28*$AD$10 -> #VALUE! | AE28: =$N28*$AE$10 -> #VALUE! | AF28: =$N28*$AF$10 -> #VALUE! | AG28: =$N28*$AG$10 -> #VALUE! | AH28: =$N28*$AH$10 -> #VALUE! | AI28: =$N28*$AI$10 -> #VALUE! | AJ28: =$N28*$AJ$10 -> #VALUE! | AK28: =$N28*$AK$10 -> #VALUE!
A29: =A28+1 -> 18 | B29: Packaging | G29: Không yêu cầu | J29: =IF(ISERROR(1000000*H29/$E$2),"",1000000*H29/$E$2) -> 0 | K29: =J29*$K$11*$N$9/1000000 -> 0 | L29: =J29*$L$11*$N$9/1000000 -> 0 | M29: =IF(I29<K29,"Cần order thêm",IF(I29>L29,"Quá nhiều hàng tồn","")) | N29: =IF(M29="Cần order thêm",L29-I29,"") | Q29: =$N29*$Q$10 -> #VALUE! | R29: =$N29*$R$10 -> #VALUE! | S29: =$N29*$S$10 -> #VALUE! | T29: =$N29*$T$10 -> #VALUE! | U29: =$N29*$U$10 -> #VALUE! | V29: =$N29*$V$10 -> #VALUE! | W29: =$N29*$W$10 -> #VALUE! | X29: =$N29*$X$10 -> #VALUE! | Y29: =$N29*$Y$10 -> #VALUE! | Z29: =$N29*$Z$10 -> #VALUE! | AA29: =$N29*$AA$10 -> #VALUE! | AB29: =$N29*$AB$10 -> #VALUE! | AC29: =$N29*$AC$10 -> #VALUE! | AD29: =$N29*$AD$10 -> #VALUE! | AE29: =$N29*$AE$10 -> #VALUE! | AF29: =$N29*$AF$10 -> #VALUE! | AG29: =$N29*$AG$10 -> #VALUE! | AH29: =$N29*$AH$10 -> #VALUE! | AI29: =$N29*$AI$10 -> #VALUE! | AJ29: =$N29*$AJ$10 -> #VALUE! | AK29: =$N29*$AK$10 -> #VALUE!
A30: =A29+1 -> 19 | B30: Packaging | G30: Không yêu cầu | J30: =IF(ISERROR(1000000*H30/$E$2),"",1000000*H30/$E$2) -> 0 | K30: =J30*$K$11*$N$9/1000000 -> 0 | L30: =J30*$L$11*$N$9/1000000 -> 0 | M30: =IF(I30<K30,"Cần order thêm",IF(I30>L30,"Quá nhiều hàng tồn","")) | N30: =IF(M30="Cần order thêm",L30-I30,"") | Q30: =$N30*$Q$10 -> #VALUE! | R30: =$N30*$R$10 -> #VALUE! | S30: =$N30*$S$10 -> #VALUE! | T30: =$N30*$T$10 -> #VALUE! | U30: =$N30*$U$10 -> #VALUE! | V30: =$N30*$V$10 -> #VALUE! | W30: =$N30*$W$10 -> #VALUE! | X30: =$N30*$X$10 -> #VALUE! | Y30: =$N30*$Y$10 -> #VALUE! | Z30: =$N30*$Z$10 -> #VALUE! | AA30: =$N30*$AA$10 -> #VALUE! | AB30: =$N30*$AB$10 -> #VALUE! | AC30: =$N30*$AC$10 -> #VALUE! | AD30: =$N30*$AD$10 -> #VALUE! | AE30: =$N30*$AE$10 -> #VALUE! | AF30: =$N30*$AF$10 -> #VALUE! | AG30: =$N30*$AG$10 -> #VALUE! | AH30: =$N30*$AH$10 -> #VALUE! | AI30: =$N30*$AI$10 -> #VALUE! | AJ30: =$N30*$AJ$10 -> #VALUE! | AK30: =$N30*$AK$10 -> #VALUE!
A31: =A30+1 -> 20 | B31: Packaging | G31: Không yêu cầu | J31: =IF(ISERROR(1000000*H31/$E$2),"",1000000*H31/$E$2) -> 0 | K31: =J31*$K$11*$N$9/1000000 -> 0 | L31: =J31*$L$11*$N$9/1000000 -> 0 | M31: =IF(I31<K31,"Cần order thêm",IF(I31>L31,"Quá nhiều hàng tồn","")) | N31: =IF(M31="Cần order thêm",L31-I31,"") | Q31: =$N31*$Q$10 -> #VALUE! | R31: =$N31*$R$10 -> #VALUE! | S31: =$N31*$S$10 -> #VALUE! | T31: =$N31*$T$10 -> #VALUE! | U31: =$N31*$U$10 -> #VALUE! | V31: =$N31*$V$10 -> #VALUE! | W31: =$N31*$W$10 -> #VALUE! | X31: =$N31*$X$10 -> #VALUE! | Y31: =$N31*$Y$10 -> #VALUE! | Z31: =$N31*$Z$10 -> #VALUE! | AA31: =$N31*$AA$10 -> #VALUE! | AB31: =$N31*$AB$10 -> #VALUE! | AC31: =$N31*$AC$10 -> #VALUE! | AD31: =$N31*$AD$10 -> #VALUE! | AE31: =$N31*$AE$10 -> #VALUE! | AF31: =$N31*$AF$10 -> #VALUE! | AG31: =$N31*$AG$10 -> #VALUE! | AH31: =$N31*$AH$10 -> #VALUE! | AI31: =$N31*$AI$10 -> #VALUE! | AJ31: =$N31*$AJ$10 -> #VALUE! | AK31: =$N31*$AK$10 -> #VALUE!
A32: =A31+1 -> 21 | B32: Packaging | G32: Không yêu cầu | J32: =IF(ISERROR(1000000*H32/$E$2),"",1000000*H32/$E$2) -> 0 | K32: =J32*$K$11*$N$9/1000000 -> 0 | L32: =J32*$L$11*$N$9/1000000 -> 0 | M32: =IF(I32<K32,"Cần order thêm",IF(I32>L32,"Quá nhiều hàng tồn","")) | N32: =IF(M32="Cần order thêm",L32-I32,"") | Q32: =$N32*$Q$10 -> #VALUE! | R32: =$N32*$R$10 -> #VALUE! | S32: =$N32*$S$10 -> #VALUE! | T32: =$N32*$T$10 -> #VALUE! | U32: =$N32*$U$10 -> #VALUE! | V32: =$N32*$V$10 -> #VALUE! | W32: =$N32*$W$10 -> #VALUE! | X32: =$N32*$X$10 -> #VALUE! | Y32: =$N32*$Y$10 -> #VALUE! | Z32: =$N32*$Z$10 -> #VALUE! | AA32: =$N32*$AA$10 -> #VALUE! | AB32: =$N32*$AB$10 -> #VALUE! | AC32: =$N32*$AC$10 -> #VALUE! | AD32: =$N32*$AD$10 -> #VALUE! | AE32: =$N32*$AE$10 -> #VALUE! | AF32: =$N32*$AF$10 -> #VALUE! | AG32: =$N32*$AG$10 -> #VALUE! | AH32: =$N32*$AH$10 -> #VALUE! | AI32: =$N32*$AI$10 -> #VALUE! | AJ32: =$N32*$AJ$10 -> #VALUE! | AK32: =$N32*$AK$10 -> #VALUE!
A33: =A32+1 -> 22 | B33: Packaging | G33: 5kg | J33: =IF(ISERROR(1000000*H33/$E$2),"",1000000*H33/$E$2) -> 0 | K33: =J33*$K$11*$N$9/1000000 -> 0 | L33: =J33*$L$11*$N$9/1000000 -> 0 | M33: =IF(I33<K33,"Cần order thêm",IF(I33>L33,"Quá nhiều hàng tồn","")) | N33: =IF(M33="Cần order thêm",L33-I33,"") | Q33: =$N33*$Q$10 -> #VALUE! | R33: =$N33*$R$10 -> #VALUE! | S33: =$N33*$S$10 -> #VALUE! | T33: =$N33*$T$10 -> #VALUE! | U33: =$N33*$U$10 -> #VALUE! | V33: =$N33*$V$10 -> #VALUE! | W33: =$N33*$W$10 -> #VALUE! | X33: =$N33*$X$10 -> #VALUE! | Y33: =$N33*$Y$10 -> #VALUE! | Z33: =$N33*$Z$10 -> #VALUE! | AA33: =$N33*$AA$10 -> #VALUE! | AB33: =$N33*$AB$10 -> #VALUE! | AC33: =$N33*$AC$10 -> #VALUE! | AD33: =$N33*$AD$10 -> #VALUE! | AE33: =$N33*$AE$10 -> #VALUE! | AF33: =$N33*$AF$10 -> #VALUE! | AG33: =$N33*$AG$10 -> #VALUE! | AH33: =$N33*$AH$10 -> #VALUE! | AI33: =$N33*$AI$10 -> #VALUE! | AJ33: =$N33*$AJ$10 -> #VALUE! | AK33: =$N33*$AK$10 -> #VALUE!
A34: =A33+1 -> 23 | B34: Packaging | G34: 5kg | J34: =IF(ISERROR(1000000*H34/$E$2),"",1000000*H34/$E$2) -> 0 | K34: =J34*$K$11*$N$9/1000000 -> 0 | L34: =J34*$L$11*$N$9/1000000 -> 0 | M34: =IF(I34<K34,"Cần order thêm",IF(I34>L34,"Quá nhiều hàng tồn","")) | N34: =IF(M34="Cần order thêm",L34-I34,"") | Q34: =$N34*$Q$10 -> #VALUE! | R34: =$N34*$R$10 -> #VALUE! | S34: =$N34*$S$10 -> #VALUE! | T34: =$N34*$T$10 -> #VALUE! | U34: =$N34*$U$10 -> #VALUE! | V34: =$N34*$V$10 -> #VALUE! | W34: =$N34*$W$10 -> #VALUE! | X34: =$N34*$X$10 -> #VALUE! | Y34: =$N34*$Y$10 -> #VALUE! | Z34: =$N34*$Z$10 -> #VALUE! | AA34: =$N34*$AA$10 -> #VALUE! | AB34: =$N34*$AB$10 -> #VALUE! | AC34: =$N34*$AC$10 -> #VALUE! | AD34: =$N34*$AD$10 -> #VALUE! | AE34: =$N34*$AE$10 -> #VALUE! | AF34: =$N34*$AF$10 -> #VALUE! | AG34: =$N34*$AG$10 -> #VALUE! | AH34: =$N34*$AH$10 -> #VALUE! | AI34: =$N34*$AI$10 -> #VALUE! | AJ34: =$N34*$AJ$10 -> #VALUE! | AK34: =$N34*$AK$10 -> #VALUE!
A35: =A34+1 -> 24 | B35: Packaging | G35: 5kg | J35: =IF(ISERROR(1000000*H35/$E$2),"",1000000*H35/$E$2) -> 0 | K35: =J35*$K$11*$N$9/1000000 -> 0 | L35: =J35*$L$11*$N$9/1000000 -> 0 | M35: =IF(I35<K35,"Cần order thêm",IF(I35>L35,"Quá nhiều hàng tồn","")) | N35: =IF(M35="Cần order thêm",L35-I35,"") | Q35: =$N35*$Q$10 -> #VALUE! | R35: =$N35*$R$10 -> #VALUE! | S35: =$N35*$S$10 -> #VALUE! | T35: =$N35*$T$10 -> #VALUE! | U35: =$N35*$U$10 -> #VALUE! | V35: =$N35*$V$10 -> #VALUE! | W35: =$N35*$W$10 -> #VALUE! | X35: =$N35*$X$10 -> #VALUE! | Y35: =$N35*$Y$10 -> #VALUE! | Z35: =$N35*$Z$10 -> #VALUE! | AA35: =$N35*$AA$10 -> #VALUE! | AB35: =$N35*$AB$10 -> #VALUE! | AC35: =$N35*$AC$10 -> #VALUE! | AD35: =$N35*$AD$10 -> #VALUE! | AE35: =$N35*$AE$10 -> #VALUE! | AF35: =$N35*$AF$10 -> #VALUE! | AG35: =$N35*$AG$10 -> #VALUE! | AH35: =$N35*$AH$10 -> #VALUE! | AI35: =$N35*$AI$10 -> #VALUE! | AJ35: =$N35*$AJ$10 -> #VALUE! | AK35: =$N35*$AK$10 -> #VALUE!
A36: =A35+1 -> 25 | B36: Consumable | G36: 2 Btl | J36: =IF(ISERROR(1000000*H36/$E$2),"",1000000*H36/$E$2) -> 0 | K36: =J36*$K$11*$N$9/1000000 -> 0 | L36: =J36*$L$11*$N$9/1000000 -> 0 | M36: =IF(I36<K36,"Cần order thêm",IF(I36>L36,"Quá nhiều hàng tồn","")) | N36: =IF(M36="Cần order thêm",L36-I36,"") | Q36: =$N36*$Q$10 -> #VALUE! | R36: =$N36*$R$10 -> #VALUE! | S36: =$N36*$S$10 -> #VALUE! | T36: =$N36*$T$10 -> #VALUE! | U36: =$N36*$U$10 -> #VALUE! | V36: =$N36*$V$10 -> #VALUE! | W36: =$N36*$W$10 -> #VALUE! | X36: =$N36*$X$10 -> #VALUE! | Y36: =$N36*$Y$10 -> #VALUE! | Z36: =$N36*$Z$10 -> #VALUE! | AA36: =$N36*$AA$10 -> #VALUE! | AB36: =$N36*$AB$10 -> #VALUE! | AC36: =$N36*$AC$10 -> #VALUE! | AD36: =$N36*$AD$10 -> #VALUE! | AE36: =$N36*$AE$10 -> #VALUE! | AF36: =$N36*$AF$10 -> #VALUE! | AG36: =$N36*$AG$10 -> #VALUE! | AH36: =$N36*$AH$10 -> #VALUE! | AI36: =$N36*$AI$10 -> #VALUE! | AJ36: =$N36*$AJ$10 -> #VALUE! | AK36: =$N36*$AK$10 -> #VALUE!
A37: =A36+1 -> 26 | B37: Consumable | G37: 1000 Pcs | J37: =IF(ISERROR(1000000*H37/$E$2),"",1000000*H37/$E$2) -> 0 | K37: =J37*$K$11*$N$9/1000000 -> 0 | L37: =J37*$L$11*$N$9/1000000 -> 0 | M37: =IF(I37<K37,"Cần order thêm",IF(I37>L37,"Quá nhiều hàng tồn","")) | N37: =IF(M37="Cần order thêm",L37-I37,"") | Q37: =$N37*$Q$10 -> #VALUE! | R37: =$N37*$R$10 -> #VALUE! | S37: =$N37*$S$10 -> #VALUE! | T37: =$N37*$T$10 -> #VALUE! | U37: =$N37*$U$10 -> #VALUE! | V37: =$N37*$V$10 -> #VALUE! | W37: =$N37*$W$10 -> #VALUE! | X37: =$N37*$X$10 -> #VALUE! | Y37: =$N37*$Y$10 -> #VALUE! | Z37: =$N37*$Z$10 -> #VALUE! | AA37: =$N37*$AA$10 -> #VALUE! | AB37: =$N37*$AB$10 -> #VALUE! | AC37: =$N37*$AC$10 -> #VALUE! | AD37: =$N37*$AD$10 -> #VALUE! | AE37: =$N37*$AE$10 -> #VALUE! | AF37: =$N37*$AF$10 -> #VALUE! | AG37: =$N37*$AG$10 -> #VALUE! | AH37: =$N37*$AH$10 -> #VALUE! | AI37: =$N37*$AI$10 -> #VALUE! | AJ37: =$N37*$AJ$10 -> #VALUE! | AK37: =$N37*$AK$10 -> #VALUE!
